Workbook

Sheet Structural
A1: DT | B1: High Arch Severity | C1: Nose Cone Severity | D1: Inside Web Plates Severity | E1: Hoist Plates Severity | F1: Top & Bottom flange Severity | G1: HTM Severity | H1: Crack Length Criteria | I1: Weighted criteria | J1: Total Lenghts cracks (mm) | K1: Accum front brake | L1: Accum rear brake | M1: Accum steer right | N1: Accum steer left | O1: Alternator | P1: Operator Cab | Q1: Frame | R1: Hoist cylinder right | S1: Hoist cylinder left | T1: Steer cylinder right | U1: Steer cylinder left | V1: Final Drive right | W1: Final Drive left | X1: Engine | Y1: Eletrical motor right | Z1: Eletrical motor left | AA1: Spindle right | AB1: Spindle left | AC1: Front strut right | AD1: Rear strtus right | AE1: Front strut left | AF1: Rear strut right | AG1: Body | AH1: Kits 1 A/C System | AI1: Kit 2 Lube system | AJ1: Kit 3 Hydraulic filters & seal kits | AK1: Kit 4 Operator Cab Monuting | AL1: Kit 5 Drive system | AM1: Kit 6 Drive system elfa fan blower | AN1: Kit 7 Drive system braking resistor | AO1: Kit 8 Body Mounting & Pads | AP1: Kit 9 Accum steer & Brake | AQ1: Kit 10 Brake Valve & Cooler mounting | AR1: Kit 11 Front axle & MTG | AS1: Kit 12 Frame Bottom plate optimized | AT1: Kit 13 Frame upper plate optimized | AU1: Kit 14 Frame left side optimized | AV1: Kit 15 Frame right side optimized | AW1: Kit 16 Hoist plate reinforment optmized | AX1: Kit 17 Filtration drive system optmized | AY1: Kit 18 Engine & Hardware | AZ1: Kit 19 Mirror bracket support | BA1: Kit 20 Fuel tank Bracket support | BB1: Accum front brake | BC1: Accum rear brake | BD1: Accum steer right | BE1: Accum steer left | BF1: Alternator | BG1: Operator Cab | BH1: Hoist cylinder right | BI1: Hoist cylinder left | BJ1: Steer cylinder right | BK1: Steer cylinder left | BL1: Final Drive right | BM1: Final Drive left | BN1: Engine | BO1: Eletrical motor right | BP1: Eletrical motor left | BQ1: Front strut right | BR1: Rear strtus right | BS1: Front strut left | BT1: Rear strut left | BU1: Body reapirs | BV1: Hours | BW1: Labour CHM per Kit | BX1: Backlog total Labour | BY1: Total Labour | BZ1: Total cost per kit | CA1: Cost per Components | CB1: Total cost Labour Components | CC1: Total cost parts components | CD1: Total cost Chome & Mechanized | CE1: Total cost per truck
A2: 823 | B2: 1 | C2: 1 | D2: 1 | E2: 1 | F2: 1 | G2: 0.5 | H2: 0 | I2: 0 | J2: 0 | K2: 0.80901417 | L2: 1.0757492 | M2: 0.70318389 | N2: 0.70318389 | O2: 0.18529524 | P2: 0.43029967 | Q2: 1.0948793 | R2: 0.02926875 | S2: 0.54873625 | T2: 0.438989 | U2: 0.513539 | V2: 0.085544444 | W2: 0.27092111 | X2: 0.18529524 | Y2: 0.32799333 | Z2: 0.36909333 | AA2: 1.0948793 | AB2: 1.0948793 | AC2: 0.014685 | AD2: 0.1779 | AE2: 0.16244 | AF2: 0.072392857 | AG2: 0.54187183 | AH2: 1 | AI2: 1 | AJ2: 1 | AK2: 1 | AL2: 1 | AM2: 1 | AN2: 5 | AO2: 1 | AP2: 1 | AQ2: 1 | AR2: 1 | AS2: 1 | AT2: 1 | AU2: 1 | AV2: 1 | AW2: 1 | AX2: 1 | AY2: 1 | AZ2: 1 | BA2: 1 | BB2: =IF('Rules & Rate'!$B$2<=K2,1,0) -> 1 | BC2: =IF('Rules & Rate'!$B$2<=M2,1,0) -> 1 | BD2: =IF('Rules & Rate'!$B$2<=N2,1,0) -> 1 | BE2: =IF('Rules & Rate'!$B$2<=N2,1,0) -> 1 | BF2: =IF('Rules & Rate'!$B$3<=O2,1,0) -> 0 | BG2: =IF('Rules & Rate'!$B$3<=P2,1,0) -> 0 | BH2: =IF('Rules & Rate'!$B$2<=R2,1,0) -> 0 | BI2: =IF('Rules & Rate'!$B$2<=S2,1,0) -> 0 | BJ2: =IF('Rules & Rate'!$B$2<=T2,1,0) -> 0 | BK2: =IF('Rules & Rate'!$B$2<=U2,1,0) -> 0 | BL2: =IF('Rules & Rate'!$B$4<=V2,1,0) -> 0 | BM2: =IF('Rules & Rate'!$B$4<=W2,1,0) -> 0 | BN2: =IF('Rules & Rate'!$B$5<=X2,1,0) -> 0 | BO2: =IF('Rules & Rate'!$B$3<=Y2,1,0) -> 0 | BP2: =IF('Rules & Rate'!$B$3<=Z2,1,0) -> 0 | BQ2: =IF('Rules & Rate'!$B$2<=AD2,1,0) -> 0 | BR2: =IF('Rules & Rate'!$B$2<=AE2,1,0) -> 0 | BS2: =IF('Rules & Rate'!$B$2<=AF2,1,0) -> 0 | BT2: =IF('Rules & Rate'!$B$2<=AG2,1,0) -> 0 | BU2: =IF('Rules & Rate'!$B$6<=AG2,1,0) -> 0 | BV2: 65692.76 | BW2: =SUMPRODUCT(AH2:BA2,Labour!$B$2:$U$2) -> 400 | BX2: 130 | BY2: =+BW2+BX2 -> 530 | BZ2: =SUMPRODUCT(AH2:BA2,Labour!$B$3:$U$3) -> 273459.23 | CA2: =SUMPRODUCT(BB2:BU2,'Component $'!$B$10:$U$10) -> 20970.68 | CB2: =SUMPRODUCT(BB2:BU2,'Component $'!$B$9:$U$9) -> 2982.78 | CC2: =SUMPRODUCT(BB2:BU2,'Component $'!$B$6:$U$6) -> 1393.9 | CD2: =SUMPRODUCT(BB2:BU2,'Component $'!$B$8:$U$8) -> 16594 | CE2: =+BZ2+CA2 -> 294429.91
A3: 824 | B3: 2 | C3: 1 | D3: 1 | E3: 2 | F3: 2 | G3: 0.8 | H3: 0.55620155 | I3: 0.44496124 | J3: 2870 | K3: 1.6743508 | L3: 1.6743508 | M3: 0.37944806 | N3: 0.77956167 | O3: 0.20693333 | P3: 0.45588233 | Q3: 1.1138715 | R3: 0.41377125 | S3: 0.34818375 | T3: 1.4986035 | U3: 0.388802 | V3: 0.24288889 | W3: 0.24288889 | X3: 0.20693333 | Y3: 0.24288889 | Z3: 0.24288889 | AA3: 0.70542767 | AB3: 1.1138715 | AC3: 0.267927 | AD3: 0.098985714 | AF3: 0.31228571 | AG3: 0.6163825 | AH3: 1 | AI3: 1 | AJ3: 1 | AK3: 1 | AL3: 1 | AM3: 1 | AN3: 2 | AO3: 1 | AP3: 1 | AQ3: 1 | AR3: 1 | AS3: 1 | AT3: 1 | AU3: 1 | AV3: 1 | AW3: 1 | AX3: 1 | AY3: 1 | AZ3: 1 | BA3: 1 | BB3: =IF('Rules & Rate'!$B$2<=K3,1,0) -> 1 | BC3: =IF('Rules & Rate'!$B$2<=L3,1,0) -> 1 | BD3: =IF('Rules & Rate'!$B$2<=N3,1,0) -> 1 | BE3: =IF('Rules & Rate'!$B$2<=N3,1,0) -> 1 | BF3: =IF('Rules & Rate'!$B$3<=O3,1,0) -> 0 | BG3: =IF('Rules & Rate'!$B$3<=P3,1,0) -> 0 | BH3: =IF('Rules & Rate'!$B$2<=R3,1,0) -> 0 | BI3: =IF('Rules & Rate'!$B$2<=S3,1,0) -> 0 | BJ3: =IF('Rules & Rate'!$B$2<=T3,1,0) -> 1 | BK3: =IF('Rules & Rate'!$B$2<=U3,1,0) -> 0 | BL3: =IF('Rules & Rate'!$B$4<=V3,1,0) -> 0 | BM3: =IF('Rules & Rate'!$B$4<=W3,1,0) -> 0 | BN3: =IF('Rules & Rate'!$B$5<=X3,1,0) -> 0 | BO3: =IF('Rules & Rate'!$B$3<=Y3,1,0) -> 0 | BP3: =IF('Rules & Rate'!$B$3<=Z3,1,0) -> 0 | BQ3: =IF('Rules & Rate'!$B$2<=AD3,1,0) -> 0 | BR3: =IF('Rules & Rate'!$B$2<=AE3,1,0) -> 0 | BS3: =IF('Rules & Rate'!$B$2<=AF3,1,0) -> 0 | BT3: =IF('Rules & Rate'!$B$2<=AG3,1,0) -> 0 | BU3: =IF('Rules & Rate'!$B$6<=AG3,1,0) -> 0 | BV3: 66758.39 | BW3: =SUMPRODUCT(AH3:BA3,Labour!$B$2:$U$2) -> 382 | BX3: 122 | BY3: =+BW3+BX3 -> 504 | BZ3: =SUMPRODUCT(AH3:BA3,Labour!$B$3:$U$3) -> 254613.23 | CA3: =SUMPRODUCT(BB3:BU3,'Component $'!$B$10:$U$10) -> 26598.325 | CB3: =SUMPRODUCT(BB3:BU3,'Component $'!$B$9:$U$9) -> 3728.475 | CC3: =SUMPRODUCT(BB3:BU3,'Component $'!$B$6:$U$6) -> 1728.85 | CD3: =SUMPRODUCT(BB3:BU3,'Component $'!$B$8:$U$8) -> 21141 | CE3: =+BZ3+CA3 -> 281211.56
A4: 825 | B4: 1 | C4: 1 | D4: 1 | E4: 1 | F4: 2 | G4: 0.6 | H4: 0.16085271 | I4: 0.096511628 | J4: 830 | K4: 1.19014 | L4: 1.19014 | M4: 0.75815528 | N4: 0.52483111 | O4: 0.47836476 | P4: 0.4761075 | Q4: 1.0866835 | R4: 0.56326 | S4: 0.26088125 | T4: 0.03827 | U4: 0.8181195 | V4: 0.42776444 | W4: 0.12475556 | X4: 0.47836476 | Y4: 0.80798556 | Z4: 0.12475556 | AA4: 1.0866835 | AB4: 1.0866835 | AC4: 0.208705 | AD4: 0.054671429 | AE4: 0.208705 | AF4: 0.19595 | AG4: 0.65410483 | AH4: 1 | AI4: 1 | AJ4: 1 | AK4: 1 | AL4: 1 | AM4: 1 | AN4: 4 | AO4: 1 | AP4: 1 | AQ4: 1 | AR4: 1 | AS4: 1 | AT4: 1 | AU4: 1 | AV4: 1 | AW4: 1 | AX4: 1 | AY4: 1 | AZ4: 1 | BA4: 1 | BB4: =IF('Rules & Rate'!$B$2<=K4,1,0) -> 1 | BC4: =IF('Rules & Rate'!$B$2<=L4,1,0) -> 1 | BD4: =IF('Rules & Rate'!$B$2<=N4,1,0) -> 0 | BE4: =IF('Rules & Rate'!$B$2<=N4,1,0) -> 0 | BF4: =IF('Rules & Rate'!$B$3<=O4,1,0) -> 0 | BG4: =IF('Rules & Rate'!$B$3<=P4,1,0) -> 0 | BH4: =IF('Rules & Rate'!$B$2<=R4,1,0) -> 0 | BI4: =IF('Rules & Rate'!$B$2<=S4,1,0) -> 0 | BJ4: =IF('Rules & Rate'!$B$2<=T4,1,0) -> 0 | BK4: =IF('Rules & Rate'!$B$2<=U4,1,0) -> 1 | BL4: =IF('Rules & Rate'!$B$4<=V4,1,0) -> 0 | BM4: =IF('Rules & Rate'!$B$4<=W4,1,0) -> 0 | BN4: =IF('Rules & Rate'!$B$5<=X4,1,0) -> 0 | BO4: =IF('Rules & Rate'!$B$3<=Y4,1,0) -> 1 | BP4: =IF('Rules & Rate'!$B$3<=Z4,1,0) -> 0 | BQ4: =IF('Rules & Rate'!$B$2<=AD4,1,0) -> 0 | BR4: =IF('Rules & Rate'!$B$2<=AE4,1,0) -> 0 | BS4: =IF('Rules & Rate'!$B$2<=AF4,1,0) -> 0 | BT4: =IF('Rules & Rate'!$B$2<=AG4,1,0) -> 1 | BU4: =IF('Rules & Rate'!$B$6<=AG4,1,0) -> 0 | BV4: 65183.41 | BW4: =SUMPRODUCT(AH4:BA4,Labour!$B$2:$U$2) -> 394 | BX4: 88 | BY4: =+BW4+BX4 -> 482 | BZ4: =SUMPRODUCT(AH4:BA4,Labour!$B$3:$U$3) -> 267177.23 | CA4: =SUMPRODUCT(BB4:BU4,'Component $'!$B$10:$U$10) -> 60218.041 | CB4: =SUMPRODUCT(BB4:BU4,'Component $'!$B$9:$U$9) -> 15070.091 | CC4: =SUMPRODUCT(BB4:BU4,'Component $'!$B$6:$U$6) -> 25388.95 | CD4: =SUMPRODUCT(BB4:BU4,'Component $'!$B$8:$U$8) -> 19759 | CE4: =+BZ4+CA4 -> 327395.27
A5: 826 | B5: 1 | C5: 1 | D5: 1 | E5: 1 | F5: 1 | G5: 0.5 | H5: 0 | I5: 0 | J5: 0 | K5: 1.2589812 | L5: 1.2589812 | M5: 0.75906194 | N5: 0.75906194 | O5: 0.050247619 | P5: 0.42165483 | Q5: 1.071602 | R5: 0.19609375 | S5: 0.03055 | T5: 0.341648 | U5: 0.393398 | V5: 0.31552 | W5: 0.18202222 | X5: 0.40845048 | Y5: 0.31552 | Z5: 0.18202222 | AA5: 1.071602 | AB5: 1.071602 | AC5: 0.466888 | AD5: 0.1519 | AE5: 0.218095 | AF5: 0.21172143 | AG5: 0.637907 | AH5: 1 | AI5: 1 | AJ5: 1 | AK5: 1 | AL5: 1 | AM5: 1 | AN5: 5 | AO5: 1 | AP5: 1 | AQ5: 1 | AR5: 1 | AS5: 1 | AT5: 1 | AU5: 1 | AV5: 1 | AW5: 1 | AX5: 1 | AY5: 1 | AZ5: 1 | BA5: 1 | BB5: =IF('Rules & Rate'!$B$2<=K5,1,0) -> 1 | BC5: =IF('Rules & Rate'!$B$2<=L5,1,0) -> 1 | BD5: =IF('Rules & Rate'!$B$2<=N5,1,0) -> 1 | BE5: =IF('Rules & Rate'!$B$2<=N5,1,0) -> 1 | BF5: =IF('Rules & Rate'!$B$3<=O5,1,0) -> 0 | BG5: =IF('Rules & Rate'!$B$3<=P5,1,0) -> 0 | BH5: =IF('Rules & Rate'!$B$2<=R5,1,0) -> 0 | BI5: =IF('Rules & Rate'!$B$2<=S5,1,0) -> 0 | BJ5: =IF('Rules & Rate'!$B$2<=T5,1,0) -> 0 | BK5: =IF('Rules & Rate'!$B$2<=U5,1,0) -> 0 | BL5: =IF('Rules & Rate'!$B$4<=V5,1,0) -> 0 | BM5: =IF('Rules & Rate'!$B$4<=W5,1,0) -> 0 | BN5: =IF('Rules & Rate'!$B$5<=X5,1,0) -> 0 | BO5: =IF('Rules & Rate'!$B$3<=Y5,1,0) -> 0 | BP5: =IF('Rules & Rate'!$B$3<=Z5,1,0) -> 0 | BQ5: =IF('Rules & Rate'!$B$2<=AD5,1,0) -> 0 | BR5: =IF('Rules & Rate'!$B$2<=AE5,1,0) -> 0 | BS5: =IF('Rules & Rate'!$B$2<=AF5,1,0) -> 0 | BT5: =IF('Rules & Rate'!$B$2<=AG5,1,0) -> 0 | BU5: =IF('Rules & Rate'!$B$6<=AG5,1,0) -> 0 | BV5: 64231.12 | BW5: =SUMPRODUCT(AH5:BA5,Labour!$B$2:$U$2) -> 400 | BX5: 97 | BY5: =+BW5+BX5 -> 497 | BZ5: =SUMPRODUCT(AH5:BA5,Labour!$B$3:$U$3) -> 273459.23 | CA5: =SUMPRODUCT(BB5:BU5,'Component $'!$B$10:$U$10) -> 20970.68 | CB5: =SUMPRODUCT(BB5:BU5,'Component $'!$B$9:$U$9) -> 2982.78 | CC5: =SUMPRODUCT(BB5:BU5,'Component $'!$B$6:$U$6) -> 1393.9 | CD5: =SUMPRODUCT(BB5:BU5,'Component $'!$B$8:$U$8) -> 16594 | CE5: =+BZ5+CA5 -> 294429.91
A6: 827 | B6: 1 | C6: 1 | D6: 1 | E6: 1 | F6: 1 | G6: 0.5 | H6: 0 | I6: 0 | J6: 0 | K6: 1.2177712 | L6: 1.2177712 | M6: 0.73301139 | O6: 0.13200952 | P6: 0.4871085 | Q6: 1.084562 | R6: 0.43108125 | S6: 0.03146875 | T6: 0.711318 | U6: 0.344885 | V6: 1.0111722 | W6: 0.61156111 | X6: 0.13200952 | Y6: 1.0109178 | Z6: 0.74300167 | AA6: 1.084562 | AB6: 1.084562 | AC6: 0.123025 | AD6: 0.14041429 | AE6: 0.175115 | AF6: 0.14041429 | AG6: 0.4871085 | AH6: 1 | AI6: 1 | AJ6: 1 | AK6: 1 | AL6: 1 | AM6: 1 | AN6: 3 | AO6: 1 | AP6: 1 | AQ6: 1 | AR6: 1 | AS6: 1 | AT6: 1 | AU6: 1 | AV6: 1 | AW6: 1 | AX6: 1 | AY6: 1 | AZ6: 1 | BA6: 1 | BB6: =IF('Rules & Rate'!$B$2<=K6,1,0) -> 1 | BC6: =IF('Rules & Rate'!$B$2<=L6,1,0) -> 1 | BD6: =IF('Rules & Rate'!$B$2<=N6,1,0) -> 0 | BE6: =IF('Rules & Rate'!$B$2<=N6,1,0) -> 0 | BF6: =IF('Rules & Rate'!$B$3<=O6,1,0) -> 0 | BG6: =IF('Rules & Rate'!$B$3<=P6,1,0) -> 0 | BH6: =IF('Rules & Rate'!$B$2<=R6,1,0) -> 0 | BI6: =IF('Rules & Rate'!$B$2<=S6,1,0) -> 0 | BJ6: =IF('Rules & Rate'!$B$2<=T6,1,0) -> 1 | BK6: =IF('Rules & Rate'!$B$2<=U6,1,0) -> 0 | BL6: =IF('Rules & Rate'!$B$4<=V6,1,0) -> 1 | BM6: =IF('Rules & Rate'!$B$4<=W6,1,0) -> 0 | BN6: =IF('Rules & Rate'!$B$5<=X6,1,0) -> 0 | BO6: =IF('Rules & Rate'!$B$3<=Y6,1,0) -> 1 | BP6: =IF('Rules & Rate'!$B$3<=Z6,1,0) -> 1 | BQ6: =IF('Rules & Rate'!$B$2<=AD6,1,0) -> 0 | BR6: =IF('Rules & Rate'!$B$2<=AE6,1,0) -> 0 | BS6: =IF('Rules & Rate'!$B$2<=AF6,1,0) -> 0 | BT6: =IF('Rules & Rate'!$B$2<=AG6,1,0) -> 0 | BU6: =IF('Rules & Rate'!$B$6<=AG6,1,0) -> 0 | BV6: 65001.72 | BW6: =SUMPRODUCT(AH6:BA6,Labour!$B$2:$U$2) -> 388 | BX6: 127 | BY6: =+BW6+BX6 -> 515 | BZ6: =SUMPRODUCT(AH6:BA6,Labour!$B$3:$U$3) -> 260895.23 | CA6: =SUMPRODUCT(BB6:BU6,'Component $'!$B$10:$U$10) -> 229855.63 | CB6: =SUMPRODUCT(BB6:BU6,'Component $'!$B$9:$U$9) -> 28700.685 | CC6: =SUMPRODUCT(BB6:BU6,'Component $'!$B$6:$U$6) -> 155707.95 | CD6: =SUMPRODUCT(BB6:BU6,'Component $'!$B$8:$U$8) -> 45447 | CE6: =+BZ6+CA6 -> 490750.87
A7: 828 | B7: 1 | C7: 1 | D7: 1 | E7: 1 | F7: 1 | G7: 0.5 | H7: 0.16860465 | I7: 0.084302326 | J7: 870 | K7: 1.8189646 | L7: 1.8189646 | M7: 0.77974528 | N7: 0.77974528 | O7: 0.43383524 | P7: 0.46137283 | Q7: 1.1150435 | R7: 0.21925625 | S7: 0.4026275 | T7: 0.09914 | U7: 0.12489 | V7: 0.13876667 | W7: 0.0067222222 | X7: 1.3182081 | Y7: 0.35345778 | Z7: 0.53308 | AA7: 1.1150435 | AB7: 1.1150435 | AC7: 0.427107 | AD7: 1.1819657 | AE7: 0.322092 | AF7: 1.1819657 | AG7: 0.661483 | AH7: 1 | AI7: 1 | AJ7: 1 | AK7: 1 | AL7: 1 | AM7: 1 | AN7: 5 | AO7: 1 | AP7: 1 | AQ7: 1 | AR7: 1 | AS7: 1 | AT7: 1 | AU7: 1 | AV7: 1 | AW7: 1 | AX7: 1 | AY7: 1 | AZ7: 1 | BA7: 1 | BB7: =IF('Rules & Rate'!$B$2<=K7,1,0) -> 1 | BC7: =IF('Rules & Rate'!$B$2<=L7,1,0) -> 1 | BD7: =IF('Rules & Rate'!$B$2<=N7,1,0) -> 1 | BE7: =IF('Rules & Rate'!$B$2<=N7,1,0) -> 1 | BF7: =IF('Rules & Rate'!$B$3<=O7,1,0) -> 0 | BG7: =IF('Rules & Rate'!$B$3<=P7,1,0) -> 0 | BH7: =IF('Rules & Rate'!$B$2<=R7,1,0) -> 0 | BI7: =IF('Rules & Rate'!$B$2<=S7,1,0) -> 0 | BJ7: =IF('Rules & Rate'!$B$2<=T7,1,0) -> 0 | BK7: =IF('Rules & Rate'!$B$2<=U7,1,0) -> 0 | BL7: =IF('Rules & Rate'!$B$4<=V7,1,0) -> 0 | BM7: =IF('Rules & Rate'!$B$4<=W7,1,0) -> 0 | BN7: =IF('Rules & Rate'!$B$5<=X7,1,0) -> 1 | BO7: =IF('Rules & Rate'!$B$3<=Y7,1,0) -> 0 | BP7: =IF('Rules & Rate'!$B$3<=Z7,1,0) -> 1 | BQ7: =IF('Rules & Rate'!$B$2<=AD7,1,0) -> 1 | BR7: =IF('Rules & Rate'!$B$2<=AE7,1,0) -> 0 | BS7: =IF('Rules & Rate'!$B$2<=AF7,1,0) -> 1 | BT7: =IF('Rules & Rate'!$B$2<=AG7,1,0) -> 1 | BU7: =IF('Rules & Rate'!$B$6<=AG7,1,0) -> 0 | BV7: 66902.61 | BW7: =SUMPRODUCT(AH7:BA7,Labour!$B$2:$U$2) -> 400 | BX7: 127 | BY7: =+BW7+BX7 -> 527 | BZ7: =SUMPRODUCT(AH7:BA7,Labour!$B$3:$U$3) -> 273459.23 | CA7: =SUMPRODUCT(BB7:BU7,'Component $'!$B$10:$U$10) -> 128208.1 | CB7: =SUMPRODUCT(BB7:BU7,'Component $'!$B$9:$U$9) -> 21147.199 | CC7: =SUMPRODUCT(BB7:BU7,'Component $'!$B$6:$U$6) -> 69850.9 | CD7: =SUMPRODUCT(BB7:BU7,'Component $'!$B$8:$U$8) -> 37210 | CE7: =+BZ7+CA7 -> 401667.33
A8: 829 | B8: 1 | C8: 1 | D8: 1 | E8: 1 | F8: 1 | G8: 0.5 | H8: 0.069767442 | I8: 0.034883721 | J8: 360 | K8: 1.5123317 | L8: 1.5123317 | M8: 0.72856111 | N8: 0.72856111 | O8: 0.35297 | P8: 0.39662433 | Q8: 1.0433083 | R8: 0.30641062 | S8: 0.04408125 | T8: 0.7103125 | U8: 1.26041 | V8: 0.527015 | W8: 0.78923611 | X8: 0.67226 | Y8: 0.18215 | Z8: 0.68977611 | AA8: 1.0433083 | AB8: 1.0433083 | AC8: 0.5280935 | AD8: 0.14952143 | AE8: 0.082245 | AF8: 0.11749286 | AG8: 0.68526517 | AH8: 1 | AI8: 1 | AJ8: 1 | AK8: 1 | AL8: 1 | AM8: 1 | AN8: 2 | AO8: 1 | AP8: 1 | AQ8: 1 | AR8: 1 | AS8: 1 | AT8: 1 | AU8: 1 | AV8: 1 | AW8: 1 | AX8: 1 | AY8: 1 | AZ8: 1 | BA8: 1 | BB8: =IF('Rules & Rate'!$B$2<=K8,1,0) -> 1 | BC8: =IF('Rules & Rate'!$B$2<=L8,1,0) -> 1 | BD8: =IF('Rules & Rate'!$B$2<=N8,1,0) -> 1 | BE8: =IF('Rules & Rate'!$B$2<=N8,1,0) -> 1 | BF8: =IF('Rules & Rate'!$B$3<=O8,1,0) -> 0 | BG8: =IF('Rules & Rate'!$B$3<=P8,1,0) -> 0 | BH8: =IF('Rules & Rate'!$B$2<=R8,1,0) -> 0 | BI8: =IF('Rules & Rate'!$B$2<=S8,1,0) -> 0 | BJ8: =IF('Rules & Rate'!$B$2<=T8,1,0) -> 1 | BK8: =IF('Rules & Rate'!$B$2<=U8,1,0) -> 1 | BL8: =IF('Rules & Rate'!$B$4<=V8,1,0) -> 0 | BM8: =IF('Rules & Rate'!$B$4<=W8,1,0) -> 1 | BN8: =IF('Rules & Rate'!$B$5<=X8,1,0) -> 0 | BO8: =IF('Rules & Rate'!$B$3<=Y8,1,0) -> 0 | BP8: =IF('Rules & Rate'!$B$3<=Z8,1,0) -> 1 | BQ8: =IF('Rules & Rate'!$B$2<=AD8,1,0) -> 0 | BR8: =IF('Rules & Rate'!$B$2<=AE8,1,0) -> 0 | BS8: =IF('Rules & Rate'!$B$2<=AF8,1,0) -> 0 | BT8: =IF('Rules & Rate'!$B$2<=AG8,1,0) -> 1 | BU8: =IF('Rules & Rate'!$B$6<=AG8,1,0) -> 0 | BV8: 62598.5 | BW8: =SUMPRODUCT(AH8:BA8,Labour!$B$2:$U$2) -> 382 | BX8: 141 | BY8: =+BW8+BX8 -> 523 | BZ8: =SUMPRODUCT(AH8:BA8,Labour!$B$3:$U$3) -> 254613.23 | CA8: =SUMPRODUCT(BB8:BU8,'Component $'!$B$10:$U$10) -> 231167.78 | CB8: =SUMPRODUCT(BB8:BU8,'Component $'!$B$9:$U$9) -> 22618.976 | CC8: =SUMPRODUCT(BB8:BU8,'Component $'!$B$6:$U$6) -> 141748.8 | CD8: =SUMPRODUCT(BB8:BU8,'Component $'!$B$8:$U$8) -> 66800 | CE8: =+BZ8+CA8 -> 485781.01
A9: 830 | B9: 1 | C9: 1 | D9: 1 | E9: 1 | F9: 1 | G9: 0.5 | H9: 0 | I9: 0 | J9: 0 | K9: 1.5782779 | L9: 1.5782779 | M9: 0.74672 | N9: 0.74672 | O9: 0.044828571 | P9: 0.405869 | Q9: 1.0600778 | R9: 0.44502313 | S9: 0.44551687 | T9: 0.008505 | U9: 1.217607 | V9: 0.94872889 | W9: 0.63883167 | X9: 0.044828571 | Y9: 0.38140944 | Z9: 0.61380944 | AA9: 1.0600778 | AB9: 1.0600778 | AC9: 0.061405 | AD9: 0.089521429 | AE9: 0.3089035 | AF9: 0.089521429 | AG9: 0.405869 | AH9: 1 | AI9: 1 | AJ9: 1 | AK9: 1 | AL9: 1 | AM9: 1 | AN9: 2 | AO9: 0 | AP9: 1 | AQ9: 1 | AR9: 1 | AS9: 1 | AT9: 1 | AU9: 1 | AV9: 1 | AW9: 1 | AX9: 1 | AY9: 1 | AZ9: 1 | BA9: 1 | BB9: =IF('Rules & Rate'!$B$2<=K9,1,0) -> 1 | BC9: =IF('Rules & Rate'!$B$2<=L9,1,0) -> 1 | BD9: =IF('Rules & Rate'!$B$2<=N9,1,0) -> 1 | BE9: =IF('Rules & Rate'!$B$2<=N9,1,0) -> 1 | BF9: =IF('Rules & Rate'!$B$3<=O9,1,0) -> 0 | BG9: =IF('Rules & Rate'!$B$3<=P9,1,0) -> 0 | BH9: =IF('Rules & Rate'!$B$2<=R9,1,0) -> 0 | BI9: =IF('Rules & Rate'!$B$2<=S9,1,0) -> 0 | BJ9: =IF('Rules & Rate'!$B$2<=T9,1,0) -> 0 | BK9: =IF('Rules & Rate'!$B$2<=U9,1,0) -> 1 | BL9: =IF('Rules & Rate'!$B$4<=V9,1,0) -> 1 | BM9: =IF('Rules & Rate'!$B$4<=W9,1,0) -> 0 | BN9: =IF('Rules & Rate'!$B$5<=X9,1,0) -> 0 | BO9: =IF('Rules & Rate'!$B$3<=Y9,1,0) -> 0 | BP9: =IF('Rules & Rate'!$B$3<=Z9,1,0) -> 1 | BQ9: =IF('Rules & Rate'!$B$2<=AD9,1,0) -> 0 | BR9: =IF('Rules & Rate'!$B$2<=AE9,1,0) -> 0 | BS9: =IF('Rules & Rate'!$B$2<=AF9,1,0) -> 0 | BT9: =IF('Rules & Rate'!$B$2<=AG9,1,0) -> 0 | BU9: =IF('Rules & Rate'!$B$6<=AG9,1,0) -> 0 | BV9: 63604.67 | BW9: =SUMPRODUCT(AH9:BA9,Labour!$B$2:$U$2) -> 370 | BX9: 186 | BY9: =+BW9+BX9 -> 556 | BZ9: =SUMPRODUCT(AH9:BA9,Labour!$B$3:$U$3) -> 242348.26 | CA9: =SUMPRODUCT(BB9:BU9,'Component $'!$B$10:$U$10) -> 210888.02 | CB9: =SUMPRODUCT(BB9:BU9,'Component $'!$B$9:$U$9) -> 19616.175 | CC9: =SUMPRODUCT(BB9:BU9,'Component $'!$B$6:$U$6) -> 136730.85 | CD9: =SUMPRODUCT(BB9:BU9,'Component $'!$B$8:$U$8) -> 54541 | CE9: =+BZ9+CA9 -> 453236.28
A10: 831 | B10: 1 | C10: 1 | D10: 1 | E10: 1 | F10: 1 | G10: 0.5 | H10: 0 | I10: 0 | J10: 0 | K10: 0.40910958 | L10: 0.40910958 | M10: 0.63515861 | N10: 0.63515861 | O10: 0.36870619 | Q10: 0.16364383 | R10: 0.02666875 | S10: 0.08853125 | T10: 1.1432855 | U10: 1.1432855 | V10: 0.54547944 | W10: 0.54547944 | X10: 0.46755381 | Y10: 0.54547944 | AA10: 0.99901617 | AB10: 0.99901617 | AC10: 0.070825 | AD10: 0.379895 | AE10: 0.070825 | AF10: 0.14987143 | AG10: 0.51296717 | AH10: 1 | AI10: 1 | AJ10: 1 | AK10: 1 | AL10: 1 | AM10: 1 | AN10: 4 | AO10: 1 | AP10: 1 | AQ10: 1 | AR10: 1 | AS10: 1 | AT10: 1 | AU10: 1 | AV10: 1 | AW10: 1 | AX10: 1 | AY10: 1 | AZ10: 1 | BA10: 1 | BB10: =IF('Rules & Rate'!$B$2<=K10,1,0) -> 0 | BC10: =IF('Rules & Rate'!$B$2<=L10,1,0) -> 0 | BD10: =IF('Rules & Rate'!$B$2<=N10,1,0) -> 0 | BE10: =IF('Rules & Rate'!$B$2<=N10,1,0) -> 0 | BF10: =IF('Rules & Rate'!$B$3<=O10,1,0) -> 0 | BG10: =IF('Rules & Rate'!$B$3<=P10,1,0) -> 0 | BH10: =IF('Rules & Rate'!$B$2<=R10,1,0) -> 0 | BI10: =IF('Rules & Rate'!$B$2<=S10,1,0) -> 0 | BJ10: =IF('Rules & Rate'!$B$2<=T10,1,0) -> 1 | BK10: =IF('Rules & Rate'!$B$2<=U10,1,0) -> 1 | BL10: =IF('Rules & Rate'!$B$4<=V10,1,0) -> 0 | BM10: =IF('Rules & Rate'!$B$4<=W10,1,0) -> 0 | BN10: =IF('Rules & Rate'!$B$5<=X10,1,0) -> 0 | BO10: =IF('Rules & Rate'!$B$3<=Y10,1,0) -> 1 | BP10: =IF('Rules & Rate'!$B$3<=Z10,1,0) -> 0 | BQ10: =IF('Rules & Rate'!$B$2<=AD10,1,0) -> 0 | BR10: =IF('Rules & Rate'!$B$2<=AE10,1,0) -> 0 | BS10: =IF('Rules & Rate'!$B$2<=AF10,1,0) -> 0 | BT10: =IF('Rules & Rate'!$B$2<=AG10,1,0) -> 0 | BU10: =IF('Rules & Rate'!$B$6<=AG10,1,0) -> 0 | BV10: 59940.97 | BW10: =SUMPRODUCT(AH10:BA10,Labour!$B$2:$U$2) -> 394 | BX10: 138 | BY10: =+BW10+BX10 -> 532 | BZ10: =SUMPRODUCT(AH10:BA10,Labour!$B$3:$U$3) -> 267177.23 | CA10: =SUMPRODUCT(BB10:BU10,'Component $'!$B$10:$U$10) -> 41478.19 | CB10: =SUMPRODUCT(BB10:BU10,'Component $'!$B$9:$U$9) -> 12067.29 | CC10: =SUMPRODUCT(BB10:BU10,'Component $'!$B$6:$U$6) -> 20316.9 | CD10: =SUMPRODUCT(BB10:BU10,'Component $'!$B$8:$U$8) -> 9094 | CE10: =+BZ10+CA10 -> 308655.42
A11: 832 | B11: 1 | C11: 1 | D11: 2 | E11: 1 | F11: 2 | G11: 0.7 | H11: 0.35852713 | I11: 0.25096899 | J11: 1850 | K11: 1.6036858 | L11: 1.6036858 | M11: 0.77221111 | N11: 0.77221111 | O11: 0.23825714 | P11: 0.4358905 | Q11: 1.0651798 | R11: 0.5074225 | S11: 0.44981625 | T11: 0.336228 | U11: 0.336228 | V11: 0.10051111 | W11: 0.15101667 | X11: 0.31245524 | Y11: 0.10051111 | Z11: 0.15101667 | AA11: 1.0651798 | AB11: 1.0651798 | AC11: 0.259158 | AD11: 0.19416429 | AE11: 0.280628 | AF11: 0.19416429 | AG11: 0.5135555 | AH11: 1 | AI11: 1 | AJ11: 1 | AK11: 1 | AL11: 1 | AM11: 1 | AN11: 2 | AO11: 1 | AP11: 1 | AQ11: 1 | AR11: 1 | AS11: 1 | AT11: 1 | AU11: 1 | AV11: 1 | AW11: 1 | AX11: 1 | AY11: 1 | AZ11: 1 | BA11: 1 | BB11: =IF('Rules & Rate'!$B$2<=K11,1,0) -> 1 | BC11: =IF('Rules & Rate'!$B$2<=L11,1,0) -> 1 | BD11: =IF('Rules & Rate'!$B$2<=N11,1,0) -> 1 | BE11: =IF('Rules & Rate'!$B$2<=N11,1,0) -> 1 | BF11: =IF('Rules & Rate'!$B$3<=O11,1,0) -> 0 | BG11: =IF('Rules & Rate'!$B$3<=P11,1,0) -> 0 | BH11: =IF('Rules & Rate'!$B$2<=R11,1,0) -> 0 | BI11: =IF('Rules & Rate'!$B$2<=S11,1,0) -> 0 | BJ11: =IF('Rules & Rate'!$B$2<=T11,1,0) -> 0 | BK11: =IF('Rules & Rate'!$B$2<=U11,1,0) -> 0 | BL11: =IF('Rules & Rate'!$B$4<=V11,1,0) -> 0 | BM11: =IF('Rules & Rate'!$B$4<=W11,1,0) -> 0 | BN11: =IF('Rules & Rate'!$B$5<=X11,1,0) -> 0 | BO11: =IF('Rules & Rate'!$B$3<=Y11,1,0) -> 0 | BP11: =IF('Rules & Rate'!$B$3<=Z11,1,0) -> 0 | BQ11: =IF('Rules & Rate'!$B$2<=AD11,1,0) -> 0 | BR11: =IF('Rules & Rate'!$B$2<=AE11,1,0) -> 0 | BS11: =IF('Rules & Rate'!$B$2<=AF11,1,0) -> 0 | BT11: =IF('Rules & Rate'!$B$2<=AG11,1,0) -> 0 | BU11: =IF('Rules & Rate'!$B$6<=AG11,1,0) -> 0 | BV11: 63857.72 | BW11: =SUMPRODUCT(AH11:BA11,Labour!$B$2:$U$2) -> 382 | BX11: 127 | BY11: =+BW11+BX11 -> 509 | BZ11: =SUMPRODUCT(AH11:BA11,Labour!$B$3:$U$3) -> 254613.23 | CA11: =SUMPRODUCT(BB11:BU11,'Component $'!$B$10:$U$10) -> 20970.68 | CB11: =SUMPRODUCT(BB11:BU11,'Component $'!$B$9:$U$9) -> 2982.78 | CC11: =SUMPRODUCT(BB11:BU11,'Component $'!$B$6:$U$6) -> 1393.9 | CD11: =SUMPRODUCT(BB11:BU11,'Component $'!$B$8:$U$8) -> 16594 | CE11: =+BZ11+CA11 -> 275583.91
A12: 833 | B12: 2 | C12: 0 | D12: 2 | E12: 2 | F12: 1 | G12: 0.7 | H12: 0.59883721 | I12: 0.41918605 | J12: 3090 | K12: 0.66243917 | L12: 0.68918375 | M12: 0.25958806 | N12: 0.25958806 | O12: 0.4032319 | P12: 0.27579317 | Q12: 0.96806933 | R12: 0.63740438 | S12: 0.63740438 | T12: 0.635064 | U12: 0.635064 | V12: 0.30549833 | W12: 0.37379833 | X12: 0.63024905 | Y12: 0.26573167 | Z12: 0.25187611 | AA12: 0.96806933 | AB12: 0.96806933 | AC12: 0.3674335 | AD12: 0.1069 | AE12: 0.138075 | AF12: 0.28698571 | AG12: 0.4892925 | AH12: 1 | AI12: 1 | AJ12: 1 | AK12: 1 | AL12: 1 | AM12: 1 | AN12: 2 | AO12: 1 | AP12: 1 | AQ12: 1 | AR12: 1 | AS12: 1 | AT12: 1 | AU12: 1 | AV12: 1 | AW12: 1 | AX12: 1 | AY12: 1 | AZ12: 1 | BA12: 1 | BB12: =IF('Rules & Rate'!$B$2<=K12,1,0) -> 1 | BC12: =IF('Rules & Rate'!$B$2<=L12,1,0) -> 1 | BD12: =IF('Rules & Rate'!$B$2<=N12,1,0) -> 0 | BE12: =IF('Rules & Rate'!$B$2<=N12,1,0) -> 0 | BF12: =IF('Rules & Rate'!$B$3<=O12,1,0) -> 0 | BG12: =IF('Rules & Rate'!$B$3<=P12,1,0) -> 0 | BH12: =IF('Rules & Rate'!$B$2<=R12,1,0) -> 0 | BI12: =IF('Rules & Rate'!$B$2<=S12,1,0) -> 0 | BJ12: =IF('Rules & Rate'!$B$2<=T12,1,0) -> 0 | BK12: =IF('Rules & Rate'!$B$2<=U12,1,0) -> 0 | BL12: =IF('Rules & Rate'!$B$4<=V12,1,0) -> 0 | BM12: =IF('Rules & Rate'!$B$4<=W12,1,0) -> 0 | BN12: =IF('Rules & Rate'!$B$5<=X12,1,0) -> 0 | BO12: =IF('Rules & Rate'!$B$3<=Y12,1,0) -> 0 | BP12: =IF('Rules & Rate'!$B$3<=Z12,1,0) -> 0 | BQ12: =IF('Rules & Rate'!$B$2<=AD12,1,0) -> 0 | BR12: =IF('Rules & Rate'!$B$2<=AE12,1,0) -> 0 | BS12: =IF('Rules & Rate'!$B$2<=AF12,1,0) -> 0 | BT12: =IF('Rules & Rate'!$B$2<=AG12,1,0) -> 0 | BU12: =IF('Rules & Rate'!$B$6<=AG12,1,0) -> 0 | BV12: 58084.16 | BW12: =SUMPRODUCT(AH12:BA12,Labour!$B$2:$U$2) -> 382 | BX12: 101 | BY12: =+BW12+BX12 -> 483 | BZ12: =SUMPRODUCT(AH12:BA12,Labour!$B$3:$U$3) -> 254613.23 | CA12: =SUMPRODUCT(BB12:BU12,'Component $'!$B$10:$U$10) -> 9715.39 | CB12: =SUMPRODUCT(BB12:BU12,'Component $'!$B$9:$U$9) -> 1491.39 | CC12: =SUMPRODUCT(BB12:BU12,'Component $'!$B$6:$U$6) -> 724 | CD12: =SUMPRODUCT(BB12:BU12,'Component $'!$B$8:$U$8) -> 7500 | CE12: =+BZ12+CA12 -> 264328.62
A13: 834 | B13: 1 | C13: 2 | D13: 2 | E13: 2 | F13: 2 | G13: 0.9 | H13: 0.40116279 | I13: 0.36104651 | J13: 2070 | K13: 1.6365787 | L13: 1.6365787 | M13: 0.69945556 | O13: 0.1689619 | P13: 0.38261667 | Q13: 1.0275835 | R13: 0.033075 | S13: 0.033075 | T13: 1.328568 | U13: 1.23262 | V13: 0.327425 | W13: 0.058238889 | X13: 0.1689619 | Y13: 0.37725833 | Z13: 0.058238889 | AA13: 1.0275835 | AB13: 1.0275835 | AC13: 0.3874325 | AD13: 0.21232857 | AE13: 0.19563 | AF13: 0.24420714 | AG13: 0.38261667 | AH13: 1 | AI13: 1 | AJ13: 1 | AK13: 1 | AL13: 1 | AM13: 1 | AN13: 2 | AO13: 1 | AP13: 1 | AQ13: 1 | AR13: 1 | AS13: 1 | AT13: 1 | AU13: 1 | AV13: 1 | AW13: 1 | AX13: 1 | AY13: 1 | AZ13: 1 | BA13: 1 | BB13: =IF('Rules & Rate'!$B$2<=K13,1,0) -> 1 | BC13: =IF('Rules & Rate'!$B$2<=L13,1,0) -> 1 | BD13: =IF('Rules & Rate'!$B$2<=N13,1,0) -> 0 | BE13: =IF('Rules & Rate'!$B$2<=N13,1,0) -> 0 | BF13: =IF('Rules & Rate'!$B$3<=O13,1,0) -> 0 | BG13: =IF('Rules & Rate'!$B$3<=P13,1,0) -> 0 | BH13: =IF('Rules & Rate'!$B$2<=R13,1,0) -> 0 | BI13: =IF('Rules & Rate'!$B$2<=S13,1,0) -> 0 | BJ13: =IF('Rules & Rate'!$B$2<=T13,1,0) -> 1 | BK13: =IF('Rules & Rate'!$B$2<=U13,1,0) -> 1 | BL13: =IF('Rules & Rate'!$B$4<=V13,1,0) -> 0 | BM13: =IF('Rules & Rate'!$B$4<=W13,1,0) -> 0 | BN13: =IF('Rules & Rate'!$B$5<=X13,1,0) -> 0 | BO13: =IF('Rules & Rate'!$B$3<=Y13,1,0) -> 0 | BP13: =IF('Rules & Rate'!$B$3<=Z13,1,0) -> 0 | BQ13: =IF('Rules & Rate'!$B$2<=AD13,1,0) -> 0 | BR13: =IF('Rules & Rate'!$B$2<=AE13,1,0) -> 0 | BS13: =IF('Rules & Rate'!$B$2<=AF13,1,0) -> 0 | BT13: =IF('Rules & Rate'!$B$2<=AG13,1,0) -> 0 | BU13: =IF('Rules & Rate'!$B$6<=AG13,1,0) -> 0 | BV13: 61655.01 | BW13: =SUMPRODUCT(AH13:BA13,Labour!$B$2:$U$2) -> 382 | BX13: 155 | BY13: =+BW13+BX13 -> 537 | BZ13: =SUMPRODUCT(AH13:BA13,Labour!$B$3:$U$3) -> 254613.23 | CA13: =SUMPRODUCT(BB13:BU13,'Component $'!$B$10:$U$10) -> 20970.68 | CB13: =SUMPRODUCT(BB13:BU13,'Component $'!$B$9:$U$9) -> 2982.78 | CC13: =SUMPRODUCT(BB13:BU13,'Component $'!$B$6:$U$6) -> 1393.9 | CD13: =SUMPRODUCT(BB13:BU13,'Component $'!$B$8:$U$8) -> 16594 | CE13: =+BZ13+CA13 -> 275583.91
A14: 835 | B14: 2 | C14: 1 | D14: 1 | E14: 1 | F14: 1 | G14: 0.6 | H14: 0.14534884 | I14: 0.087209302 | J14: 750 | K14: 1.6291617 | L14: 1.6291617 | M14: 0.19674167 | N14: 0.19674167 | O14: 0.29251429 | P14: 0.3726765 | Q14: 1.0348157 | R14: 0.63263125 | S14: 0.93949562 | T14: 0.2101 | U14: 1.214486 | V14: 0.46955 | W14: 0.11968333 | X14: 0.29251429 | Y14: 1.242255 | Z14: 0.11968333 | AA14: 1.0348157 | AB14: 1.0348157 | AC14: 0.309195 | AD14: 0.47357857 | AE14: 0.227295 | AF14: 0.2348 | AG14: 0.3726765 | AH14: 1 | AI14: 1 | AJ14: 1 | AK14: 1 | AL14: 1 | AM14: 1 | AN14: 3 | AO14: 1 | AP14: 1 | AQ14: 1 | AR14: 1 | AS14: 1 | AT14: 1 | AU14: 1 | AV14: 1 | AW14: 1 | AX14: 1 | AY14: 1 | AZ14: 1 | BA14: 1 | BB14: =IF('Rules & Rate'!$B$2<=K14,1,0) -> 1 | BC14: =IF('Rules & Rate'!$B$2<=L14,1,0) -> 1 | BD14: =IF('Rules & Rate'!$B$2<=N14,1,0) -> 0 | BE14: =IF('Rules & Rate'!$B$2<=N14,1,0) -> 0 | BF14: =IF('Rules & Rate'!$B$3<=O14,1,0) -> 0 | BG14: =IF('Rules & Rate'!$B$3<=P14,1,0) -> 0 | BH14: =IF('Rules & Rate'!$B$2<=R14,1,0) -> 0 | BI14: =IF('Rules & Rate'!$B$2<=S14,1,0) -> 1 | BJ14: =IF('Rules & Rate'!$B$2<=T14,1,0) -> 0 | BK14: =IF('Rules & Rate'!$B$2<=U14,1,0) -> 1 | BL14: =IF('Rules & Rate'!$B$4<=V14,1,0) -> 0 | BM14: =IF('Rules & Rate'!$B$4<=W14,1,0) -> 0 | BN14: =IF('Rules & Rate'!$B$5<=X14,1,0) -> 0 | BO14: =IF('Rules & Rate'!$B$3<=Y14,1,0) -> 1 | BP14: =IF('Rules & Rate'!$B$3<=Z14,1,0) -> 0 | BQ14: =IF('Rules & Rate'!$B$2<=AD14,1,0) -> 0 | BR14: =IF('Rules & Rate'!$B$2<=AE14,1,0) -> 0 | BS14: =IF('Rules & Rate'!$B$2<=AF14,1,0) -> 0 | BT14: =IF('Rules & Rate'!$B$2<=AG14,1,0) -> 0 | BU14: =IF('Rules & Rate'!$B$6<=AG14,1,0) -> 0 | BV14: 62061.74 | BW14: =SUMPRODUCT(AH14:BA14,Labour!$B$2:$U$2) -> 388 | BX14: 184 | BY14: =+BW14+BX14 -> 572 | BZ14: =SUMPRODUCT(AH14:BA14,Labour!$B$3:$U$3) -> 260895.23 | CA14: =SUMPRODUCT(BB14:BU14,'Component $'!$B$10:$U$10) -> 73087.573 | CB14: =SUMPRODUCT(BB14:BU14,'Component $'!$B$9:$U$9) -> 16216.623 | CC14: =SUMPRODUCT(BB14:BU14,'Component $'!$B$6:$U$6) -> 24922.95 | CD14: =SUMPRODUCT(BB14:BU14,'Component $'!$B$8:$U$8) -> 31948 | CE14: =+BZ14+CA14 -> 333982.8
A15: 836 | B15: 1 | C15: 1 | D15: 1 | E15: 2 | F15: 1 | G15: 0.6 | H15: 0.16666667 | I15: 0.1 | J15: 860 | K15: 1.5946988 | L15: 1.5946988 | M15: 0.70133917 | N15: 0.70133917 | O15: 0.47765286 | P15: 0.2670475 | R15: 0.62691937 | S15: 0.54403813 | T15: 0.00962 | U15: 0.3874755 | V15: 0.065183333 | W15: 0.043255556 | X15: 0.47765286 | Y15: 0.065183333 | Z15: 0.043255556 | AA15: 1.0178688 | AB15: 1.0178688 | AC15: 0.8011425 | AD15: 0.15507857 | AE15: 0.5551605 | AF15: 0.15507857 | AG15: 0.58585567 | AH15: 1 | AI15: 1 | AJ15: 1 | AK15: 1 | AL15: 1 | AM15: 1 | AN15: 2 | AO15: 1 | AP15: 1 | AQ15: 1 | AR15: 1 | AS15: 1 | AT15: 1 | AU15: 1 | AV15: 1 | AW15: 1 | AX15: 1 | AY15: 1 | AZ15: 1 | BA15: 1 | BB15: =IF('Rules & Rate'!$B$2<=K15,1,0) -> 1 | BC15: =IF('Rules & Rate'!$B$2<=L15,1,0) -> 1 | BD15: =IF('Rules & Rate'!$B$2<=N15,1,0) -> 1 | BE15: =IF('Rules & Rate'!$B$2<=N15,1,0) -> 1 | BF15: =IF('Rules & Rate'!$B$3<=O15,1,0) -> 0 | BG15: =IF('Rules & Rate'!$B$3<=P15,1,0) -> 0 | BH15: =IF('Rules & Rate'!$B$2<=R15,1,0) -> 0 | BI15: =IF('Rules & Rate'!$B$2<=S15,1,0) -> 0 | BJ15: =IF('Rules & Rate'!$B$2<=T15,1,0) -> 0 | BK15: =IF('Rules & Rate'!$B$2<=U15,1,0) -> 0 | BL15: =IF('Rules & Rate'!$B$4<=V15,1,0) -> 0 | BM15: =IF('Rules & Rate'!$B$4<=W15,1,0) -> 0 | BN15: =IF('Rules & Rate'!$B$5<=X15,1,0) -> 0 | BO15: =IF('Rules & Rate'!$B$3<=Y15,1,0) -> 0 | BP15: =IF('Rules & Rate'!$B$3<=Z15,1,0) -> 0 | BQ15: =IF('Rules & Rate'!$B$2<=AD15,1,0) -> 0 | BR15: =IF('Rules & Rate'!$B$2<=AE15,1,0) -> 0 | BS15: =IF('Rules & Rate'!$B$2<=AF15,1,0) -> 0 | BT15: =IF('Rules & Rate'!$B$2<=AG15,1,0) -> 0 | BU15: =IF('Rules & Rate'!$B$6<=AG15,1,0) -> 0 | BV15: 61073.31 | BW15: =SUMPRODUCT(AH15:BA15,Labour!$B$2:$U$2) -> 382 | BX15: 187 | BY15: =+BW15+BX15 -> 569 | BZ15: =SUMPRODUCT(AH15:BA15,Labour!$B$3:$U$3) -> 254613.23 | CA15: =SUMPRODUCT(BB15:BU15,'Component $'!$B$10:$U$10) -> 20970.68 | CB15: =SUMPRODUCT(BB15:BU15,'Component $'!$B$9:$U$9) -> 2982.78 | CC15: =SUMPRODUCT(BB15:BU15,'Component $'!$B$6:$U$6) -> 1393.9 | CD15: =SUMPRODUCT(BB15:BU15,'Component $'!$B$8:$U$8) -> 16594 | CE15: =+BZ15+CA15 -> 275583.91
A16: 837 | B16: 1 | C16: 0 | D16: 2 | E16: 2 | F16: 1 | G16: 0.6 | H16: 0.67829457 | I16: 0.40697674 | J16: 3500 | K16: 1.6071017 | L16: 1.6071017 | M16: 0.76423444 | N16: 0.76423444 | O16: 0.32863143 | P16: 0.41026817 | Q16: 1.028302 | R16: 0.24324375 | S16: 0.0216625 | T16: 0.295063 | U16: 0.295063 | V16: 0.80597944 | W16: 0.20572222 | X16: 0.68759 | Y16: 0.13995 | Z16: 0.52698111 | AA16: 1.028302 | AB16: 1.028302 | AC16: 0.395873 | AD16: 0.49292571 | AE16: 0.14705 | AF16: 0.35835714 | AG16: 0.41026817 | AH16: 1 | AI16: 1 | AJ16: 1 | AK16: 1 | AL16: 1 | AM16: 1 | AN16: 2 | AO16: 1 | AP16: 1 | AQ16: 1 | AR16: 1 | AS16: 1 | AT16: 1 | AU16: 1 | AV16: 1 | AW16: 1 | AX16: 1 | AY16: 1 | AZ16: 1 | BA16: 1 | BB16: =IF('Rules & Rate'!$B$2<=K16,1,0) -> 1 | BC16: =IF('Rules & Rate'!$B$2<=L16,1,0) -> 1 | BD16: =IF('Rules & Rate'!$B$2<=N16,1,0) -> 1 | BE16: =IF('Rules & Rate'!$B$2<=N16,1,0) -> 1 | BF16: =IF('Rules & Rate'!$B$3<=O16,1,0) -> 0 | BG16: =IF('Rules & Rate'!$B$3<=P16,1,0) -> 0 | BH16: =IF('Rules & Rate'!$B$2<=R16,1,0) -> 0 | BI16: =IF('Rules & Rate'!$B$2<=S16,1,0) -> 0 | BJ16: =IF('Rules & Rate'!$B$2<=T16,1,0) -> 0 | BK16: =IF('Rules & Rate'!$B$2<=U16,1,0) -> 0 | BL16: =IF('Rules & Rate'!$B$4<=V16,1,0) -> 1 | BM16: =IF('Rules & Rate'!$B$4<=W16,1,0) -> 0 | BN16: =IF('Rules & Rate'!$B$5<=X16,1,0) -> 0 | BO16: =IF('Rules & Rate'!$B$3<=Y16,1,0) -> 0 | BP16: =IF('Rules & Rate'!$B$3<=Z16,1,0) -> 1 | BQ16: =IF('Rules & Rate'!$B$2<=AD16,1,0) -> 0 | BR16: =IF('Rules & Rate'!$B$2<=AE16,1,0) -> 0 | BS16: =IF('Rules & Rate'!$B$2<=AF16,1,0) -> 0 | BT16: =IF('Rules & Rate'!$B$2<=AG16,1,0) -> 0 | BU16: =IF('Rules & Rate'!$B$6<=AG16,1,0) -> 0 | BV16: 61612.92 | BW16: =SUMPRODUCT(AH16:BA16,Labour!$B$2:$U$2) -> 382 | BX16: 105 | BY16: =+BW16+BX16 -> 487 | BZ16: =SUMPRODUCT(AH16:BA16,Labour!$B$3:$U$3) -> 254613.23 | CA16: =SUMPRODUCT(BB16:BU16,'Component $'!$B$10:$U$10) -> 205260.38 | CB16: =SUMPRODUCT(BB16:BU16,'Component $'!$B$9:$U$9) -> 18870.48 | CC16: =SUMPRODUCT(BB16:BU16,'Component $'!$B$6:$U$6) -> 136395.9 | CD16: =SUMPRODUCT(BB16:BU16,'Component $'!$B$8:$U$8) -> 49994 | CE16: =+BZ16+CA16 -> 459873.61
A17: 838 | B17: 1 | C17: 0 | D17: 1 | E17: 1 | F17: 1 | G17: 0.4 | H17: 0.069767442 | I17: 0.027906977 | J17: 360 | K17: 1.6641646 | L17: 1.6641646 | M17: 0.3592025 | N17: 0.78033722 | O17: 0.017957143 | P17: 0.42449417 | Q17: 1.058343 | R17: 0.65155625 | S17: 0.2965625 | T17: 0.46474 | U17: 1.4915195 | V17: 1.4149806 | W17: 1.4149806 | X17: 0.44260952 | Y17: 1.4149806 | Z17: 1.3937533 | AA17: 1.058343 | AB17: 1.058343 | AC17: 0.260875 | AD17: 0.12330714 | AE17: 0.172515 | AF17: 0.12330714 | AG17: 0.42449417 | AH17: 1 | AI17: 1 | AJ17: 1 | AK17: 1 | AL17: 1 | AM17: 1 | AN17: 2 | AO17: 0 | AP17: 1 | AQ17: 1 | AR17: 1 | AS17: 0 | AT17: 1 | AU17: 1 | AV17: 1 | AW17: 1 | AX17: 1 | AY17: 1 | AZ17: 1 | BA17: 1 | BB17: =IF('Rules & Rate'!$B$2<=K17,1,0) -> 1 | BC17: =IF('Rules & Rate'!$B$2<=L17,1,0) -> 1 | BD17: =IF('Rules & Rate'!$B$2<=N17,1,0) -> 1 | BE17: =IF('Rules & Rate'!$B$2<=N17,1,0) -> 1 | BF17: =IF('Rules & Rate'!$B$3<=O17,1,0) -> 0 | BG17: =IF('Rules & Rate'!$B$3<=P17,1,0) -> 0 | BH17: =IF('Rules & Rate'!$B$2<=R17,1,0) -> 1 | BI17: =IF('Rules & Rate'!$B$2<=S17,1,0) -> 0 | BJ17: =IF('Rules & Rate'!$B$2<=T17,1,0) -> 0 | BK17: =IF('Rules & Rate'!$B$2<=U17,1,0) -> 1 | BL17: =IF('Rules & Rate'!$B$4<=V17,1,0) -> 1 | BM17: =IF('Rules & Rate'!$B$4<=W17,1,0) -> 1 | BN17: =IF('Rules & Rate'!$B$5<=X17,1,0) -> 0 | BO17: =IF('Rules & Rate'!$B$3<=Y17,1,0) -> 1 | BP17: =IF('Rules & Rate'!$B$3<=Z17,1,0) -> 1 | BQ17: =IF('Rules & Rate'!$B$2<=AD17,1,0) -> 0 | BR17: =IF('Rules & Rate'!$B$2<=AE17,1,0) -> 0 | BS17: =IF('Rules & Rate'!$B$2<=AF17,1,0) -> 0 | BT17: =IF('Rules & Rate'!$B$2<=AG17,1,0) -> 0 | BU17: =IF('Rules & Rate'!$B$6<=AG17,1,0) -> 0 | BV17: 63478.48 | BW17: =SUMPRODUCT(AH17:BA17,Labour!$B$2:$U$2) -> 322 | BX17: 99 | BY17: =+BW17+BX17 -> 421 | BZ17: =SUMPRODUCT(AH17:BA17,Labour!$B$3:$U$3) -> 225868.27 | CA17: =SUMPRODUCT(BB17:BU17,'Component $'!$B$10:$U$10) -> 422699.36 | CB17: =SUMPRODUCT(BB17:BU17,'Component $'!$B$9:$U$9) -> 38907.513 | CC17: =SUMPRODUCT(BB17:BU17,'Component $'!$B$6:$U$6) -> 275949.85 | CD17: =SUMPRODUCT(BB17:BU17,'Component $'!$B$8:$U$8) -> 107842 | CE17: =+BZ17+CA17 -> 648567.63
A18: 839 | B18: 2 | C18: 1 | D18: 2 | E18: 2 | F18: 2 | G18: 0.9 | H18: 0.76550388 | I18: 0.68895349 | J18: 3950 | K18: 1.5707913 | L18: 1.5707913 | M18: 0.29127 | N18: 0.29127 | O18: 0.45900095 | P18: 0.26532517 | Q18: 1.0351723 | R18: 0.55203875 | S18: 0.0696625 | T18: 1.3036395 | U18: 0.7959755 | V18: 0.36094556 | W18: 0.35133444 | X18: 0.54414381 | Y18: 0.14075 | Z18: 0.57932333 | AA18: 1.0351723 | AB18: 1.0351723 | AC18: 0.306836 | AD18: 0.24573571 | AE18: 0.579431 | AF18: 0.079614286 | AG18: 0.14721033 | AH18: 1 | AI18: 1 | AJ18: 1 | AK18: 1 | AL18: 1 | AM18: 1 | AN18: 2 | AO18: 1 | AP18: 1 | AQ18: 1 | AR18: 1 | AS18: 1 | AT18: 1 | AU18: 1 | AV18: 1 | AW18: 1 | AX18: 1 | AY18: 1 | AZ18: 1 | BA18: 1 | BB18: =IF('Rules & Rate'!$B$2<=K18,1,0) -> 1 | BC18: =IF('Rules & Rate'!$B$2<=L18,1,0) -> 1 | BD18: =IF('Rules & Rate'!$B$2<=N18,1,0) -> 0 | BE18: =IF('Rules & Rate'!$B$2<=N18,1,0) -> 0 | BF18: =IF('Rules & Rate'!$B$3<=O18,1,0) -> 0 | BG18: =IF('Rules & Rate'!$B$3<=P18,1,0) -> 0 | BH18: =IF('Rules & Rate'!$B$2<=R18,1,0) -> 0 | BI18: =IF('Rules & Rate'!$B$2<=S18,1,0) -> 0 | BJ18: =IF('Rules & Rate'!$B$2<=T18,1,0) -> 1 | BK18: =IF('Rules & Rate'!$B$2<=U18,1,0) -> 1 | BL18: =IF('Rules & Rate'!$B$4<=V18,1,0) -> 0 | BM18: =IF('Rules & Rate'!$B$4<=W18,1,0) -> 0 | BN18: =IF('Rules & Rate'!$B$5<=X18,1,0) -> 0 | BO18: =IF('Rules & Rate'!$B$3<=Y18,1,0) -> 0 | BP18: =IF('Rules & Rate'!$B$3<=Z18,1,0) -> 1 | BQ18: =IF('Rules & Rate'!$B$2<=AD18,1,0) -> 0 | BR18: =IF('Rules & Rate'!$B$2<=AE18,1,0) -> 0 | BS18: =IF('Rules & Rate'!$B$2<=AF18,1,0) -> 0 | BT18: =IF('Rules & Rate'!$B$2<=AG18,1,0) -> 0 | BU18: =IF('Rules & Rate'!$B$6<=AG18,1,0) -> 0 | BV18: 62036.54 | BW18: =SUMPRODUCT(AH18:BA18,Labour!$B$2:$U$2) -> 382 | BX18: 170 | BY18: =+BW18+BX18 -> 552 | BZ18: =SUMPRODUCT(AH18:BA18,Labour!$B$3:$U$3) -> 254613.23 | CA18: =SUMPRODUCT(BB18:BU18,'Component $'!$B$10:$U$10) -> 51193.58 | CB18: =SUMPRODUCT(BB18:BU18,'Component $'!$B$9:$U$9) -> 13558.68 | CC18: =SUMPRODUCT(BB18:BU18,'Component $'!$B$6:$U$6) -> 21040.9 | CD18: =SUMPRODUCT(BB18:BU18,'Component $'!$B$8:$U$8) -> 16594 | CE18: =+BZ18+CA18 -> 305806.81
A19: 840 | B19: 1 | C19: 1 | D19: 2 | E19: 1 | F19: 1 | G19: 0.6 | H19: 0.19379845 | I19: 0.11627907 | J19: 1000 | L19: 0.78785417 | M19: 0.68427167 | N19: 0.68427167 | O19: 0.24973048 | P19: 0.31514167 | Q19: 0.99860533 | R19: 0.161225 | S19: 0.27956875 | T19: 1.3053795 | U19: 0.7448895 | V19: 0.20477222 | W19: 0.073355556 | X19: 0.7689781 | Y19: 0.20477222 | Z19: 0.073355556 | AA19: 0.99860533 | AB19: 0.99860533 | AC19: 0.08206 | AD19: 0.15488571 | AE19: 0.579657 | AF19: 0.32053571 | AG19: 0.49489717 | AH19: 1 | AI19: 1 | AJ19: 1 | AK19: 1 | AL19: 1 | AM19: 1 | AN19: 2 | AO19: 1 | AP19: 1 | AQ19: 1 | AR19: 1 | AS19: 1 | AT19: 1 | AU19: 1 | AV19: 1 | AW19: 1 | AX19: 1 | AY19: 1 | AZ19: 1 | BA19: 1 | BB19: =IF('Rules & Rate'!$B$2<=K19,1,0) -> 0 | BC19: =IF('Rules & Rate'!$B$2<=L19,1,0) -> 1 | BD19: =IF('Rules & Rate'!$B$2<=N19,1,0) -> 1 | BE19: =IF('Rules & Rate'!$B$2<=N19,1,0) -> 1 | BF19: =IF('Rules & Rate'!$B$3<=O19,1,0) -> 0 | BG19: =IF('Rules & Rate'!$B$3<=P19,1,0) -> 0 | BH19: =IF('Rules & Rate'!$B$2<=R19,1,0) -> 0 | BI19: =IF('Rules & Rate'!$B$2<=S19,1,0) -> 0 | BJ19: =IF('Rules & Rate'!$B$2<=T19,1,0) -> 1 | BK19: =IF('Rules & Rate'!$B$2<=U19,1,0) -> 1 | BL19: =IF('Rules & Rate'!$B$4<=V19,1,0) -> 0 | BM19: =IF('Rules & Rate'!$B$4<=W19,1,0) -> 0 | BN19: =IF('Rules & Rate'!$B$5<=X19,1,0) -> 1 | BO19: =IF('Rules & Rate'!$B$3<=Y19,1,0) -> 0 | BP19: =IF('Rules & Rate'!$B$3<=Z19,1,0) -> 0 | BQ19: =IF('Rules & Rate'!$B$2<=AD19,1,0) -> 0 | BR19: =IF('Rules & Rate'!$B$2<=AE19,1,0) -> 0 | BS19: =IF('Rules & Rate'!$B$2<=AF19,1,0) -> 0 | BT19: =IF('Rules & Rate'!$B$2<=AG19,1,0) -> 0 | BU19: =IF('Rules & Rate'!$B$6<=AG19,1,0) -> 0 | BV19: 59839.02 | BW19: =SUMPRODUCT(AH19:BA19,Labour!$B$2:$U$2) -> 382 | BX19: 146 | BY19: =+BW19+BX19 -> 528 | BZ19: =SUMPRODUCT(AH19:BA19,Labour!$B$3:$U$3) -> 254613.23 | CA19: =SUMPRODUCT(BB19:BU19,'Component $'!$B$10:$U$10) -> 65906.475 | CB19: =SUMPRODUCT(BB19:BU19,'Component $'!$B$9:$U$9) -> 4545.675 | CC19: =SUMPRODUCT(BB19:BU19,'Component $'!$B$6:$U$6) -> 39422.8 | CD19: =SUMPRODUCT(BB19:BU19,'Component $'!$B$8:$U$8) -> 21938 | CE19: =+BZ19+CA19 -> 320519.71
A20: 841 | B20: 1 | C20: 0 | D20: 1 | E20: 1 | F20: 1 | G20: 0.4 | H20: 0 | I20: 0 | J20: 0 | K20: 0.53639125 | L20: 0.53639125 | M20: 0.66284667 | N20: 0.66284667 | O20: 0.61301857 | P20: 0.2145565 | Q20: 0.2145565 | R20: 0.09220625 | S20: 0.121425 | T20: 0.3725445 | U20: 0.4468295 | V20: 0.97462 | W20: 1.135815 | X20: 0.61301857 | Y20: 0.71518833 | Z20: 0.71518833 | AA20: 0.9681 | AB20: 0.9681 | AC20: 0.09714 | AD20: 0.27532857 | AE20: 0.2791345 | AF20: 0.27532857 | AG20: 0.2145565 | AH20: 1 | AI20: 1 | AJ20: 1 | AK20: 1 | AL20: 1 | AM20: 1 | AN20: 3 | AO20: 0 | AP20: 1 | AQ20: 1 | AR20: 1 | AS20: 0 | AT20: 1 | AU20: 1 | AV20: 1 | AW20: 1 | AX20: 1 | AY20: 1 | AZ20: 1 | BA20: 1 | BB20: =IF('Rules & Rate'!$B$2<=K20,1,0) -> 0 | BC20: =IF('Rules & Rate'!$B$2<=L20,1,0) -> 0 | BD20: =IF('Rules & Rate'!$B$2<=N20,1,0) -> 1 | BE20: =IF('Rules & Rate'!$B$2<=N20,1,0) -> 1 | BF20: =IF('Rules & Rate'!$B$3<=O20,1,0) -> 1 | BG20: =IF('Rules & Rate'!$B$3<=P20,1,0) -> 0 | BH20: =IF('Rules & Rate'!$B$2<=R20,1,0) -> 0 | BI20: =IF('Rules & Rate'!$B$2<=S20,1,0) -> 0 | BJ20: =IF('Rules & Rate'!$B$2<=T20,1,0) -> 0 | BK20: =IF('Rules & Rate'!$B$2<=U20,1,0) -> 0 | BL20: =IF('Rules & Rate'!$B$4<=V20,1,0) -> 1 | BM20: =IF('Rules & Rate'!$B$4<=W20,1,0) -> 1 | BN20: =IF('Rules & Rate'!$B$5<=X20,1,0) -> 0 | BO20: =IF('Rules & Rate'!$B$3<=Y20,1,0) -> 1 | BP20: =IF('Rules & Rate'!$B$3<=Z20,1,0) -> 1 | BQ20: =IF('Rules & Rate'!$B$2<=AD20,1,0) -> 0 | BR20: =IF('Rules & Rate'!$B$2<=AE20,1,0) -> 0 | BS20: =IF('Rules & Rate'!$B$2<=AF20,1,0) -> 0 | BT20: =IF('Rules & Rate'!$B$2<=AG20,1,0) -> 0 | BU20: =IF('Rules & Rate'!$B$6<=AG20,1,0) -> 0 | BV20: 58086.01 | BW20: =SUMPRODUCT(AH20:BA20,Labour!$B$2:$U$2) -> 328 | BX20: 122 | BY20: =+BW20+BX20 -> 450 | BZ20: =SUMPRODUCT(AH20:BA20,Labour!$B$3:$U$3) -> 232150.26 | CA20: =SUMPRODUCT(BB20:BU20,'Component $'!$B$10:$U$10) -> 410635.59 | CB20: =SUMPRODUCT(BB20:BU20,'Component $'!$B$9:$U$9) -> 43842.69 | CC20: =SUMPRODUCT(BB20:BU20,'Component $'!$B$6:$U$6) -> 290898.9 | CD20: =SUMPRODUCT(BB20:BU20,'Component $'!$B$8:$U$8) -> 75894 | CE20: =+BZ20+CA20 -> 642785.85
A21: 842 | B21: 1 | C21: 0 | D21: 1 | E21: 1 | F21: 1 | G21: 0.4 | H21: 0 | I21: 0 | J21: 0 | K21: 0.43228542 | L21: 0.43228542 | M21: 0.59740028 | N21: 0.59740028 | O21: 0.21965952 | P21: 0.89830867 | Q21: 0.17291417 | R21: 0.14578125 | S21: 0.14578125 | T21: 0.00991 | U21: 0.904417 | V21: 0.057344444 | W21: 0.57638056 | X21: 0.49404048 | Y21: 0.57638056 | Z21: 0.57638056 | AA21: 0.89830867 | AB21: 0.89830867 | AC21: 0.08472 | AD21: 0.16660714 | AE21: 0.08472 | AF21: 0.74106071 | AG21: 0.89830867 | AH21: 1 | AI21: 1 | AJ21: 1 | AK21: 1 | AL21: 1 | AM21: 1 | AN21: 4 | AO21: 1 | AP21: 1 | AQ21: 1 | AR21: 1 | AS21: 0 | AT21: 1 | AU21: 1 | AV21: 1 | AW21: 1 | AX21: 1 | AY21: 1 | AZ21: 1 | BA21: 1 | BB21: =IF('Rules & Rate'!$B$2<=K21,1,0) -> 0 | BC21: =IF('Rules & Rate'!$B$2<=L21,1,0) -> 0 | BD21: =IF('Rules & Rate'!$B$2<=N21,1,0) -> 0 | BE21: =IF('Rules & Rate'!$B$2<=N21,1,0) -> 0 | BF21: =IF('Rules & Rate'!$B$3<=O21,1,0) -> 0 | BG21: =IF('Rules & Rate'!$B$3<=P21,1,0) -> 1 | BH21: =IF('Rules & Rate'!$B$2<=R21,1,0) -> 0 | BI21: =IF('Rules & Rate'!$B$2<=S21,1,0) -> 0 | BJ21: =IF('Rules & Rate'!$B$2<=T21,1,0) -> 0 | BK21: =IF('Rules & Rate'!$B$2<=U21,1,0) -> 1 | BL21: =IF('Rules & Rate'!$B$4<=V21,1,0) -> 0 | BM21: =IF('Rules & Rate'!$B$4<=W21,1,0) -> 0 | BN21: =IF('Rules & Rate'!$B$5<=X21,1,0) -> 0 | BO21: =IF('Rules & Rate'!$B$3<=Y21,1,0) -> 1 | BP21: =IF('Rules & Rate'!$B$3<=Z21,1,0) -> 1 | BQ21: =IF('Rules & Rate'!$B$2<=AD21,1,0) -> 0 | BR21: =IF('Rules & Rate'!$B$2<=AE21,1,0) -> 0 | BS21: =IF('Rules & Rate'!$B$2<=AF21,1,0) -> 1 | BT21: =IF('Rules & Rate'!$B$2<=AG21,1,0) -> 1 | BU21: =IF('Rules & Rate'!$B$6<=AG21,1,0) -> 1 | BV21: 53901.38 | BW21: =SUMPRODUCT(AH21:BA21,Labour!$B$2:$U$2) -> 346 | BX21: 178 | BY21: =+BW21+BX21 -> 524 | BZ21: =SUMPRODUCT(AH21:BA21,Labour!$B$3:$U$3) -> 250697.24 | CA21: =SUMPRODUCT(BB21:BU21,'Component $'!$B$10:$U$10) -> 130919.38 | CB21: =SUMPRODUCT(BB21:BU21,'Component $'!$B$9:$U$9) -> 36708.428 | CC21: =SUMPRODUCT(BB21:BU21,'Component $'!$B$6:$U$6) -> 68699.95 | CD21: =SUMPRODUCT(BB21:BU21,'Component $'!$B$8:$U$8) -> 25511 | CE21: =+BZ21+CA21 -> 381616.62
A22: 843 | B22: 1 | C22: 0 | D22: 1 | E22: 2 | F22: 0 | G22: 0.4 | H22: 0.13953488 | I22: 0.055813953 | J22: 720 | K22: 0.73590875 | L22: 0.73590875 | M22: 0.47830944 | N22: 0.3663625 | O22: 0.78167857 | P22: 0.29311617 | Q22: 0.9553255 | R22: 0.73158437 | S22: 0.60630938 | T22: 0.758124 | U22: 0.5383675 | V22: 0.31763611 | W22: 1.2400994 | X22: 0.78167857 | Y22: 0.31653611 | AA22: 0.9553255 | AB22: 0.9553255 | AC22: 0.09418 | AD22: 0.099607143 | AE22: 0.09418 | AF22: 0.20407143 | AG22: 0.9553255 | AH22: 1 | AI22: 1 | AJ22: 1 | AK22: 1 | AL22: 1 | AM22: 1 | AN22: 4 | AO22: 1 | AP22: 1 | AQ22: 1 | AR22: 1 | AS22: 0 | AT22: 0 | AU22: 1 | AV22: 1 | AW22: 1 | AX22: 1 | AY22: 1 | AZ22: 1 | BA22: 1 | BB22: =IF('Rules & Rate'!$B$2<=K22,1,0) -> 1 | BC22: =IF('Rules & Rate'!$B$2<=L22,1,0) -> 1 | BD22: =IF('Rules & Rate'!$B$2<=N22,1,0) -> 0 | BE22: =IF('Rules & Rate'!$B$2<=N22,1,0) -> 0 | BF22: =IF('Rules & Rate'!$B$3<=O22,1,0) -> 1 | BG22: =IF('Rules & Rate'!$B$3<=P22,1,0) -> 0 | BH22: =IF('Rules & Rate'!$B$2<=R22,1,0) -> 1 | BI22: =IF('Rules & Rate'!$B$2<=S22,1,0) -> 0 | BJ22: =IF('Rules & Rate'!$B$2<=T22,1,0) -> 1 | BK22: =IF('Rules & Rate'!$B$2<=U22,1,0) -> 0 | BL22: =IF('Rules & Rate'!$B$4<=V22,1,0) -> 0 | BM22: =IF('Rules & Rate'!$B$4<=W22,1,0) -> 1 | BN22: =IF('Rules & Rate'!$B$5<=X22,1,0) -> 1 | BO22: =IF('Rules & Rate'!$B$3<=Y22,1,0) -> 0 | BP22: =IF('Rules & Rate'!$B$3<=Z22,1,0) -> 0 | BQ22: =IF('Rules & Rate'!$B$2<=AD22,1,0) -> 0 | BR22: =IF('Rules & Rate'!$B$2<=AE22,1,0) -> 0 | BS22: =IF('Rules & Rate'!$B$2<=AF22,1,0) -> 0 | BT22: =IF('Rules & Rate'!$B$2<=AG22,1,0) -> 1 | BU22: =IF('Rules & Rate'!$B$6<=AG22,1,0) -> 1 | BV22: 57319.53 | BW22: =SUMPRODUCT(AH22:BA22,Labour!$B$2:$U$2) -> 298 | BX22: 185 | BY22: =+BW22+BX22 -> 483 | BZ22: =SUMPRODUCT(AH22:BA22,Labour!$B$3:$U$3) -> 236173.19 | CA22: =SUMPRODUCT(BB22:BU22,'Component $'!$B$10:$U$10) -> 302501.68 | CB22: =SUMPRODUCT(BB22:BU22,'Component $'!$B$9:$U$9) -> 30731.729 | CC22: =SUMPRODUCT(BB22:BU22,'Component $'!$B$6:$U$6) -> 191909.95 | CD22: =SUMPRODUCT(BB22:BU22,'Component $'!$B$8:$U$8) -> 79860 | CE22: =+BZ22+CA22 -> 538674.87
A23: 844 | B23: 1 | C23: 1 | D23: 2 | E23: 1 | F23: 0 | G23: 0.5 | H23: 0.18023256 | I23: 0.090116279 | J23: 930 | K23: 0.50611042 | L23: 0.50611042 | M23: 0.75047111 | N23: 0.75047111 | O23: 0.35014524 | P23: 0.98781067 | Q23: 0.20244417 | R23: 0.93364375 | S23: 0.13405625 | T23: 0.107345 | U23: 0.107345 | V23: 0.22408889 | W23: 0.032444444 | X23: 0.5784119 | Y23: 0.67481389 | Z23: 0.67476389 | AA23: 0.98781067 | AB23: 0.98781067 | AC23: 0.3718875 | AD23: 0.33708571 | AE23: 0.6073325 | AF23: 0.29926429 | AG23: 0.98781067 | AH23: 1 | AI23: 1 | AJ23: 1 | AK23: 1 | AL23: 1 | AM23: 1 | AN23: 2 | AO23: 0 | AP23: 1 | AQ23: 1 | AR23: 1 | AS23: 1 | AT23: 0 | AU23: 1 | AV23: 1 | AW23: 1 | AX23: 1 | AY23: 1 | AZ23: 1 | BA23: 1 | BB23: =IF('Rules & Rate'!$B$2<=K23,1,0) -> 0 | BC23: =IF('Rules & Rate'!$B$2<=L23,1,0) -> 0 | BD23: =IF('Rules & Rate'!$B$2<=N23,1,0) -> 1 | BE23: =IF('Rules & Rate'!$B$2<=N23,1,0) -> 1 | BF23: =IF('Rules & Rate'!$B$3<=O23,1,0) -> 0 | BG23: =IF('Rules & Rate'!$B$3<=P23,1,0) -> 1 | BH23: =IF('Rules & Rate'!$B$2<=R23,1,0) -> 1 | BI23: =IF('Rules & Rate'!$B$2<=S23,1,0) -> 0 | BJ23: =IF('Rules & Rate'!$B$2<=T23,1,0) -> 0 | BK23: =IF('Rules & Rate'!$B$2<=U23,1,0) -> 0 | BL23: =IF('Rules & Rate'!$B$4<=V23,1,0) -> 0 | BM23: =IF('Rules & Rate'!$B$4<=W23,1,0) -> 0 | BN23: =IF('Rules & Rate'!$B$5<=X23,1,0) -> 0 | BO23: =IF('Rules & Rate'!$B$3<=Y23,1,0) -> 1 | BP23: =IF('Rules & Rate'!$B$3<=Z23,1,0) -> 1 | BQ23: =IF('Rules & Rate'!$B$2<=AD23,1,0) -> 0 | BR23: =IF('Rules & Rate'!$B$2<=AE23,1,0) -> 0 | BS23: =IF('Rules & Rate'!$B$2<=AF23,1,0) -> 0 | BT23: =IF('Rules & Rate'!$B$2<=AG23,1,0) -> 1 | BU23: =IF('Rules & Rate'!$B$6<=AG23,1,0) -> 1 | BV23: 59163.34 | BW23: =SUMPRODUCT(AH23:BA23,Labour!$B$2:$U$2) -> 322 | BX23: 192 | BY23: =+BW23+BX23 -> 514 | BZ23: =SUMPRODUCT(AH23:BA23,Labour!$B$3:$U$3) -> 227824.21 | CA23: =SUMPRODUCT(BB23:BU23,'Component $'!$B$10:$U$10) -> 152156.55 | CB23: =SUMPRODUCT(BB23:BU23,'Component $'!$B$9:$U$9) -> 38600.654 | CC23: =SUMPRODUCT(BB23:BU23,'Component $'!$B$6:$U$6) -> 70048.9 | CD23: =SUMPRODUCT(BB23:BU23,'Component $'!$B$8:$U$8) -> 43507 | CE23: =+BZ23+CA23 -> 379980.76
A24: 845 | B24: 1 | C24: 1 | D24: 1 | E24: 2 | F24: 1 | G24: 0.6 | H24: 0.46124031 | I24: 0.27674419 | J24: 2380 | K24: 0.45362708 | L24: 0.45362708 | M24: 0.30638472 | N24: 0.30638472 | O24: 0.51843095 | P24: 0.9648125 | Q24: 0.18145083 | R24: 0.2617 | S24: 0.17585 | T24: 1.153738 | U24: 0.06271 | V24: 0.60483611 | W24: 0.15631111 | X24: 0.51843095 | Y24: 0.475025 | Z24: 0.15631111 | AA24: 0.9648125 | AB24: 0.9648125 | AC24: 0.5443525 | AD24: 0.019785714 | AE24: 0.090055 | AF24: 0.019785714 | AG24: 0.9648125 | AH24: 1 | AI24: 1 | AJ24: 1 | AK24: 1 | AL24: 1 | AM24: 1 | AN24: 2 | AO24: 1 | AP24: 1 | AQ24: 1 | AR24: 1 | AS24: 1 | AT24: 1 | AU24: 1 | AV24: 1 | AW24: 1 | AX24: 1 | AY24: 1 | AZ24: 1 | BA24: 1 | BB24: =IF('Rules & Rate'!$B$2<=K24,1,0) -> 0 | BC24: =IF('Rules & Rate'!$B$2<=L24,1,0) -> 0 | BD24: =IF('Rules & Rate'!$B$2<=N24,1,0) -> 0 | BE24: =IF('Rules & Rate'!$B$2<=N24,1,0) -> 0 | BF24: =IF('Rules & Rate'!$B$3<=O24,1,0) -> 1 | BG24: =IF('Rules & Rate'!$B$3<=P24,1,0) -> 1 | BH24: =IF('Rules & Rate'!$B$2<=R24,1,0) -> 0 | BI24: =IF('Rules & Rate'!$B$2<=S24,1,0) -> 0 | BJ24: =IF('Rules & Rate'!$B$2<=T24,1,0) -> 1 | BK24: =IF('Rules & Rate'!$B$2<=U24,1,0) -> 0 | BL24: =IF('Rules & Rate'!$B$4<=V24,1,0) -> 0 | BM24: =IF('Rules & Rate'!$B$4<=W24,1,0) -> 0 | BN24: =IF('Rules & Rate'!$B$5<=X24,1,0) -> 0 | BO24: =IF('Rules & Rate'!$B$3<=Y24,1,0) -> 0 | BP24: =IF('Rules & Rate'!$B$3<=Z24,1,0) -> 0 | BQ24: =IF('Rules & Rate'!$B$2<=AD24,1,0) -> 0 | BR24: =IF('Rules & Rate'!$B$2<=AE24,1,0) -> 0 | BS24: =IF('Rules & Rate'!$B$2<=AF24,1,0) -> 0 | BT24: =IF('Rules & Rate'!$B$2<=AG24,1,0) -> 1 | BU24: =IF('Rules & Rate'!$B$6<=AG24,1,0) -> 1 | BV24: 57888.75 | BW24: =SUMPRODUCT(AH24:BA24,Labour!$B$2:$U$2) -> 382 | BX24: 174 | BY24: =+BW24+BX24 -> 556 | BZ24: =SUMPRODUCT(AH24:BA24,Labour!$B$3:$U$3) -> 254613.23 | CA24: =SUMPRODUCT(BB24:BU24,'Component $'!$B$10:$U$10) -> 89362.371 | CB24: =SUMPRODUCT(BB24:BU24,'Component $'!$B$9:$U$9) -> 23875.421 | CC24: =SUMPRODUCT(BB24:BU24,'Component $'!$B$6:$U$6) -> 46427.95 | CD24: =SUMPRODUCT(BB24:BU24,'Component $'!$B$8:$U$8) -> 19059 | CE24: =+BZ24+CA24 -> 343975.6
A25: 846 | B25: 1 | C25: 0 | D25: 1 | E25: 1 | F25: 1 | G25: 0.4 | H25: 0.096899225 | I25: 0.03875969 | J25: 500 | K25: 0.76016333 | L25: 0.76016333 | M25: 0.76737444 | N25: 0.76737444 | O25: 0.8687581 | P25: 0.30406533 | Q25: 0.970018 | R25: 0.31133 | S25: 0.19045625 | T25: 0 | U25: 0.695525 | V25: 0.087838889 | W25: 0.47514333 | X25: 0.8687581 | Y25: 0.087838889 | Z25: 1.0135511 | AA25: 0.970018 | AB25: 0.970018 | AC25: 0.801356 | AD25: 0.088528571 | AE25: 0.464969 | AF25: 0.18425714 | AG25: 0.30406533 | AH25: 1 | AI25: 1 | AJ25: 1 | AK25: 1 | AL25: 1 | AM25: 1 | AN25: 3 | AO25: 1 | AP25: 1 | AQ25: 1 | AR25: 1 | AS25: 0 | AT25: 1 | AU25: 1 | AV25: 1 | AW25: 1 | AX25: 1 | AY25: 1 | AZ25: 1 | BA25: 1 | BB25: =IF('Rules & Rate'!$B$2<=K25,1,0) -> 1 | BC25: =IF('Rules & Rate'!$B$2<=L25,1,0) -> 1 | BD25: =IF('Rules & Rate'!$B$2<=N25,1,0) -> 1 | BE25: =IF('Rules & Rate'!$B$2<=N25,1,0) -> 1 | BF25: =IF('Rules & Rate'!$B$3<=O25,1,0) -> 1 | BG25: =IF('Rules & Rate'!$B$3<=P25,1,0) -> 0 | BH25: =IF('Rules & Rate'!$B$2<=R25,1,0) -> 0 | BI25: =IF('Rules & Rate'!$B$2<=S25,1,0) -> 0 | BJ25: =IF('Rules & Rate'!$B$2<=T25,1,0) -> 0 | BK25: =IF('Rules & Rate'!$B$2<=U25,1,0) -> 1 | BL25: =IF('Rules & Rate'!$B$4<=V25,1,0) -> 0 | BM25: =IF('Rules & Rate'!$B$4<=W25,1,0) -> 0 | BN25: =IF('Rules & Rate'!$B$5<=X25,1,0) -> 1 | BO25: =IF('Rules & Rate'!$B$3<=Y25,1,0) -> 0 | BP25: =IF('Rules & Rate'!$B$3<=Z25,1,0) -> 1 | BQ25: =IF('Rules & Rate'!$B$2<=AD25,1,0) -> 0 | BR25: =IF('Rules & Rate'!$B$2<=AE25,1,0) -> 0 | BS25: =IF('Rules & Rate'!$B$2<=AF25,1,0) -> 0 | BT25: =IF('Rules & Rate'!$B$2<=AG25,1,0) -> 0 | BU25: =IF('Rules & Rate'!$B$6<=AG25,1,0) -> 0 | BV25: 58168.48 | BW25: =SUMPRODUCT(AH25:BA25,Labour!$B$2:$U$2) -> 340 | BX25: 182 | BY25: =+BW25+BX25 -> 522 | BZ25: =SUMPRODUCT(AH25:BA25,Labour!$B$3:$U$3) -> 244415.24 | CA25: =SUMPRODUCT(BB25:BU25,'Component $'!$B$10:$U$10) -> 126160.33 | CB25: =SUMPRODUCT(BB25:BU25,'Component $'!$B$9:$U$9) -> 25697.475 | CC25: =SUMPRODUCT(BB25:BU25,'Component $'!$B$6:$U$6) -> 79321.85 | CD25: =SUMPRODUCT(BB25:BU25,'Component $'!$B$8:$U$8) -> 21141 | CE25: =+BZ25+CA25 -> 370575.57
A26: 847 | B26: 1 | C26: 1 | D26: 2 | E26: 2 | F26: 2 | G26: 0.8 | H26: 1 | I26: 0.8 | J26: 5160 | K26: 0.66458 | L26: 0.66458 | M26: 0.66856722 | N26: 0.66856722 | O26: 0.12678095 | P26: 0.265832 | Q26: 0.93504967 | R26: 0.99687 | S26: 0.99687 | T26: 0.9861025 | U26: 0.9861025 | V26: 0.14891111 | W26: 0.14891111 | X26: 0.12678095 | Y26: 1.3619644 | Z26: 0.29001222 | AA26: 0.93504967 | AB26: 0.93504967 | AC26: 0.569386 | AD26: 0.28374286 | AE26: 0.18017 | AF26: 0.24990714 | AG26: 0.93504967 | AH26: 1 | AI26: 1 | AJ26: 1 | AK26: 1 | AL26: 1 | AM26: 1 | AN26: 2 | AO26: 1 | AP26: 1 | AQ26: 1 | AR26: 1 | AS26: 1 | AT26: 1 | AU26: 1 | AV26: 1 | AW26: 1 | AX26: 1 | AY26: 1 | AZ26: 1 | BA26: 1 | BB26: =IF('Rules & Rate'!$B$2<=K26,1,0) -> 1 | BC26: =IF('Rules & Rate'!$B$2<=L26,1,0) -> 1 | BD26: =IF('Rules & Rate'!$B$2<=N26,1,0) -> 1 | BE26: =IF('Rules & Rate'!$B$2<=N26,1,0) -> 1 | BF26: =IF('Rules & Rate'!$B$3<=O26,1,0) -> 0 | BG26: =IF('Rules & Rate'!$B$3<=P26,1,0) -> 0 | BH26: =IF('Rules & Rate'!$B$2<=R26,1,0) -> 1 | BI26: =IF('Rules & Rate'!$B$2<=S26,1,0) -> 1 | BJ26: =IF('Rules & Rate'!$B$2<=T26,1,0) -> 1 | BK26: =IF('Rules & Rate'!$B$2<=U26,1,0) -> 1 | BL26: =IF('Rules & Rate'!$B$4<=V26,1,0) -> 0 | BM26: =IF('Rules & Rate'!$B$4<=W26,1,0) -> 0 | BN26: =IF('Rules & Rate'!$B$5<=X26,1,0) -> 0 | BO26: =IF('Rules & Rate'!$B$3<=Y26,1,0) -> 1 | BP26: =IF('Rules & Rate'!$B$3<=Z26,1,0) -> 0 | BQ26: =IF('Rules & Rate'!$B$2<=AD26,1,0) -> 0 | BR26: =IF('Rules & Rate'!$B$2<=AE26,1,0) -> 0 | BS26: =IF('Rules & Rate'!$B$2<=AF26,1,0) -> 0 | BT26: =IF('Rules & Rate'!$B$2<=AG26,1,0) -> 1 | BU26: =IF('Rules & Rate'!$B$6<=AG26,1,0) -> 1 | BV26: 55992.98 | BW26: =SUMPRODUCT(AH26:BA26,Labour!$B$2:$U$2) -> 382 | BX26: 180 | BY26: =+BW26+BX26 -> 562 | BZ26: =SUMPRODUCT(AH26:BA26,Labour!$B$3:$U$3) -> 254613.23 | CA26: =SUMPRODUCT(BB26:BU26,'Component $'!$B$10:$U$10) -> 153723.25 | CB26: =SUMPRODUCT(BB26:BU26,'Component $'!$B$9:$U$9) -> 30243.452 | CC26: =SUMPRODUCT(BB26:BU26,'Component $'!$B$6:$U$6) -> 43477.8 | CD26: =SUMPRODUCT(BB26:BU26,'Component $'!$B$8:$U$8) -> 80002 | CE26: =+BZ26+CA26 -> 408336.48
A27: 848 | B27: 2 | C27: 0 | D27: 1 | E27: 2 | F27: 1 | G27: 0.6 | H27: 0.15503876 | I27: 0.093023256 | J27: 800 | K27: 0.42574125 | L27: 0.42574125 | M27: 0.68668306 | N27: 0.68668306 | O27: 0.48844238 | P27: 0.95747533 | Q27: 0.1702965 | R27: 0.55072438 | S27: 0.64108062 | T27: 0.020885 | U27: 0.5128245 | V27: 0.567655 | W27: 0.567655 | X27: 0.48844238 | Y27: 0.567655 | Z27: 0.44719389 | AA27: 0.95747533 | AB27: 0.95747533 | AC27: 0.4428945 | AD27: 0.420585 | AE27: 0.5108895 | AF27: 0.35202143 | AG27: 0.95747533 | AH27: 1 | AI27: 1 | AJ27: 1 | AK27: 1 | AL27: 1 | AM27: 1 | AN27: 3 | AO27: 1 | AP27: 1 | AQ27: 1 | AR27: 1 | AS27: 0 | AT27: 1 | AU27: 1 | AV27: 1 | AW27: 1 | AX27: 1 | AY27: 1 | AZ27: 1 | BA27: 1 | BB27: =IF('Rules & Rate'!$B$2<=K27,1,0) -> 0 | BC27: =IF('Rules & Rate'!$B$2<=L27,1,0) -> 0 | BD27: =IF('Rules & Rate'!$B$2<=N27,1,0) -> 1 | BE27: =IF('Rules & Rate'!$B$2<=N27,1,0) -> 1 | BF27: =IF('Rules & Rate'!$B$3<=O27,1,0) -> 0 | BG27: =IF('Rules & Rate'!$B$3<=P27,1,0) -> 1 | BH27: =IF('Rules & Rate'!$B$2<=R27,1,0) -> 0 | BI27: =IF('Rules & Rate'!$B$2<=S27,1,0) -> 0 | BJ27: =IF('Rules & Rate'!$B$2<=T27,1,0) -> 0 | BK27: =IF('Rules & Rate'!$B$2<=U27,1,0) -> 0 | BL27: =IF('Rules & Rate'!$B$4<=V27,1,0) -> 0 | BM27: =IF('Rules & Rate'!$B$4<=W27,1,0) -> 0 | BN27: =IF('Rules & Rate'!$B$5<=X27,1,0) -> 0 | BO27: =IF('Rules & Rate'!$B$3<=Y27,1,0) -> 1 | BP27: =IF('Rules & Rate'!$B$3<=Z27,1,0) -> 0 | BQ27: =IF('Rules & Rate'!$B$2<=AD27,1,0) -> 0 | BR27: =IF('Rules & Rate'!$B$2<=AE27,1,0) -> 0 | BS27: =IF('Rules & Rate'!$B$2<=AF27,1,0) -> 0 | BT27: =IF('Rules & Rate'!$B$2<=AG27,1,0) -> 1 | BU27: =IF('Rules & Rate'!$B$6<=AG27,1,0) -> 1 | BV27: 57381.52 | BW27: =SUMPRODUCT(AH27:BA27,Labour!$B$2:$U$2) -> 340 | BX27: 197 | BY27: =+BW27+BX27 -> 537 | BZ27: =SUMPRODUCT(AH27:BA27,Labour!$B$3:$U$3) -> 244415.24 | CA27: =SUMPRODUCT(BB27:BU27,'Component $'!$B$10:$U$10) -> 94412.016 | CB27: =SUMPRODUCT(BB27:BU27,'Component $'!$B$9:$U$9) -> 24621.116 | CC27: =SUMPRODUCT(BB27:BU27,'Component $'!$B$6:$U$6) -> 46184.9 | CD27: =SUMPRODUCT(BB27:BU27,'Component $'!$B$8:$U$8) -> 23606 | CE27: =+BZ27+CA27 -> 338827.26
A28: 849 | B28: 1 | C28: 0 | D28: 2 | E28: 2 | F28: 0 | G28: 0.5 | H28: 0.58139535 | I28: 0.29069767 | J28: 3000 | K28: 1.4743921 | L28: 1.1795137 | M28: 0.58472667 | N28: 0.586115 | O28: 0.42998667 | P28: 0.58975683 | Q28: 0.58975683 | R28: 0.155625 | S28: 0.79022625 | T28: 0.8204245 | U28: 0.9025295 | V28: 0.067216667 | W28: 0.23485 | X28: 0.42998667 | Y28: 0.57174 | Z28: 0.49307333 | AA28: 0.58975683 | AB28: 0.58975683 | AC28: 0.488346 | AD28: 0.064964286 | AE28: 0.149105 | AF28: 0.24755714 | AG28: 0.58975683 | AH28: 1 | AI28: 1 | AJ28: 1 | AK28: 1 | AL28: 1 | AM28: 1 | AN28: 2 | AO28: 1 | AP28: 1 | AQ28: 1 | AR28: 1 | AS28: 1 | AT28: 1 | AU28: 1 | AV28: 1 | AW28: 1 | AX28: 1 | AY28: 1 | AZ28: 1 | BA28: 1 | BB28: =IF('Rules & Rate'!$B$2<=K28,1,0) -> 1 | BC28: =IF('Rules & Rate'!$B$2<=L28,1,0) -> 1 | BD28: =IF('Rules & Rate'!$B$2<=N28,1,0) -> 0 | BE28: =IF('Rules & Rate'!$B$2<=N28,1,0) -> 0 | BF28: =IF('Rules & Rate'!$B$3<=O28,1,0) -> 0 | BG28: =IF('Rules & Rate'!$B$3<=P28,1,0) -> 1 | BH28: =IF('Rules & Rate'!$B$2<=R28,1,0) -> 0 | BI28: =IF('Rules & Rate'!$B$2<=S28,1,0) -> 1 | BJ28: =IF('Rules & Rate'!$B$2<=T28,1,0) -> 1 | BK28: =IF('Rules & Rate'!$B$2<=U28,1,0) -> 1 | BL28: =IF('Rules & Rate'!$B$4<=V28,1,0) -> 0 | BM28: =IF('Rules & Rate'!$B$4<=W28,1,0) -> 0 | BN28: =IF('Rules & Rate'!$B$5<=X28,1,0) -> 0 | BO28: =IF('Rules & Rate'!$B$3<=Y28,1,0) -> 1 | BP28: =IF('Rules & Rate'!$B$3<=Z28,1,0) -> 0 | BQ28: =IF('Rules & Rate'!$B$2<=AD28,1,0) -> 0 | BR28: =IF('Rules & Rate'!$B$2<=AE28,1,0) -> 0 | BS28: =IF('Rules & Rate'!$B$2<=AF28,1,0) -> 0 | BT28: =IF('Rules & Rate'!$B$2<=AG28,1,0) -> 0 | BU28: =IF('Rules & Rate'!$B$6<=AG28,1,0) -> 0 | BV28: 35281.41 | BW28: =SUMPRODUCT(AH28:BA28,Labour!$B$2:$U$2) -> 382 | BX28: 196 | BY28: =+BW28+BX28 -> 578 | BZ28: =SUMPRODUCT(AH28:BA28,Labour!$B$3:$U$3) -> 254613.23 | CA28: =SUMPRODUCT(BB28:BU28,'Component $'!$B$10:$U$10) -> 95417.938 | CB28: =SUMPRODUCT(BB28:BU28,'Component $'!$B$9:$U$9) -> 21130.038 | CC28: =SUMPRODUCT(BB28:BU28,'Component $'!$B$6:$U$6) -> 37792.9 | CD28: =SUMPRODUCT(BB28:BU28,'Component $'!$B$8:$U$8) -> 36495 | CE28: =+BZ28+CA28 -> 350031.17
